
  You can now view your Streamlit app in your browser.

  Local URL: http://localhost:8501
  Network URL: http://192.168.1.107:8501

  % Total    % Received % Xferd  Average Speed   Time    Time     Time  Current
                                 Dload  Upload   Total   Spent    Left  Speed
  0     0    0     0    0     0      0      0 --:--:-- --:--:-- --:--:--     0  0     0    0     0    0     0      0      0 --:--:-- --:--:-- --:--:--     0
curl: (7) Failed to connect to localhost port 5677: Connection refused
2024-07-09 17:10:40.043 Uncaught app exception
Traceback (most recent call last):
  File "/home/user_n/anaconda3/envs/env_proj_8/lib/python3.10/site-packages/streamlit/runtime/scriptrunner/script_runner.py", line 589, in _run_script
    exec(code, module.__dict__)
  File "/home/user_n/Documents/Dev/git/project_8/pages/👨‍🏫_dashboard.py", line 66, in <module>
    float_1_score = my.get_li_scores(df_selected_record)[0]
  File "/home/user_n/Documents/Dev/git/project_8/utils/my_functions.py", line 57, in get_li_scores
    dict_predictions     = eval(str_dict_predictions) # {"predictions": [0]}
  File "<string>", line 0
    
SyntaxError: invalid syntax
  % Total    % Received % Xferd  Average Speed   Time    Time     Time  Current
                                 Dload  Upload   Total   Spent    Left  Speed
  0     0    0     0    0     0      0      0 --:--:-- --:--:-- --:--:--     0  0     0    0     0    0     0      0      0 --:--:-- --:--:-- --:--:--     0
curl: (7) Failed to connect to localhost port 5677: Connection refused
2024-07-09 17:11:44.721 Uncaught app exception
Traceback (most recent call last):
  File "/home/user_n/anaconda3/envs/env_proj_8/lib/python3.10/site-packages/streamlit/runtime/scriptrunner/script_runner.py", line 589, in _run_script
    exec(code, module.__dict__)
  File "/home/user_n/Documents/Dev/git/project_8/pages/👨‍🏫_dashboard.py", line 66, in <module>
    float_1_score = my.get_li_scores(df_selected_record)[0]
  File "/home/user_n/Documents/Dev/git/project_8/utils/my_functions.py", line 57, in get_li_scores
    dict_predictions     = eval(str_dict_predictions) # {"predictions": [0]}
  File "<string>", line 0
    
SyntaxError: invalid syntax
2024-07-09 17:16:31.875 Uncaught app exception
Traceback (most recent call last):
  File "/home/user_n/anaconda3/envs/env_proj_8/lib/python3.10/site-packages/streamlit/runtime/scriptrunner/script_runner.py", line 589, in _run_script
    exec(code, module.__dict__)
  File "/home/user_n/Documents/Dev/git/project_8/pages/👨‍🏫_dashboard.py", line 11, in <module>
    import my_functions as my		         # Custom module
  File "/home/user_n/Documents/Dev/git/project_8/utils/my_functions.py", line 11
    st.markdown(str_message)
                            ^
IndentationError: unindent does not match any outer indentation level
2024-07-09 17:19:14.663 Uncaught app exception
Traceback (most recent call last):
  File "/home/user_n/anaconda3/envs/env_proj_8/lib/python3.10/site-packages/streamlit/runtime/scriptrunner/script_runner.py", line 589, in _run_script
    exec(code, module.__dict__)
  File "/home/user_n/Documents/Dev/git/project_8/pages/👨‍🏫_dashboard.py", line 11, in <module>
    import my_functions as my		         # Custom module
  File "/home/user_n/Documents/Dev/git/project_8/utils/my_functions.py", line 11
    st.markdown(str_message)
                            ^
IndentationError: unindent does not match any outer indentation level
2024-07-09 17:20:20.725 Uncaught app exception
Traceback (most recent call last):
  File "/home/user_n/anaconda3/envs/env_proj_8/lib/python3.10/site-packages/streamlit/runtime/scriptrunner/script_runner.py", line 589, in _run_script
    exec(code, module.__dict__)
  File "/home/user_n/Documents/Dev/git/project_8/pages/👨‍🏫_dashboard.py", line 10, in <module>
    import my_functions as my		         # Custom module
  File "/home/user_n/Documents/Dev/git/project_8/utils/my_functions.py", line 11
    st.markdown(str_message)
                            ^
IndentationError: unindent does not match any outer indentation level
2024-07-09 17:20:49.219 Uncaught app exception
Traceback (most recent call last):
  File "/home/user_n/anaconda3/envs/env_proj_8/lib/python3.10/site-packages/streamlit/runtime/scriptrunner/script_runner.py", line 589, in _run_script
    exec(code, module.__dict__)
  File "/home/user_n/Documents/Dev/git/project_8/pages/👨‍🏫_dashboard.py", line 10, in <module>
    import my_functions as my                # Custom module
  File "/home/user_n/Documents/Dev/git/project_8/utils/my_functions.py", line 11
    st.markdown(str_message)
                            ^
IndentationError: unindent does not match any outer indentation level
2024-07-09 17:21:23.256 Uncaught app exception
Traceback (most recent call last):
  File "/home/user_n/anaconda3/envs/env_proj_8/lib/python3.10/site-packages/streamlit/runtime/scriptrunner/script_runner.py", line 589, in _run_script
    exec(code, module.__dict__)
  File "/home/user_n/Documents/Dev/git/project_8/pages/👨‍🏫_dashboard.py", line 10, in <module>
    import my_functions as my                # Custom module
  File "/home/user_n/Documents/Dev/git/project_8/utils/my_functions.py", line 11
    st.markdown(str_message)
                            ^
IndentationError: unindent does not match any outer indentation level
2024-07-09 17:22:34.162 Uncaught app exception
Traceback (most recent call last):
  File "/home/user_n/anaconda3/envs/env_proj_8/lib/python3.10/site-packages/streamlit/runtime/scriptrunner/script_runner.py", line 589, in _run_script
    exec(code, module.__dict__)
  File "/home/user_n/Documents/Dev/git/project_8/pages/👨‍🏫_dashboard.py", line 10, in <module>
    import my_functions as my                # Custom module
  File "/home/user_n/Documents/Dev/git/project_8/utils/my_functions.py", line 11
    st.markdown(str_message)
                            ^
IndentationError: unindent does not match any outer indentation level
2024-07-09 17:22:55.065 Uncaught app exception
Traceback (most recent call last):
  File "/home/user_n/anaconda3/envs/env_proj_8/lib/python3.10/site-packages/streamlit/runtime/scriptrunner/script_runner.py", line 589, in _run_script
    exec(code, module.__dict__)
  File "/home/user_n/Documents/Dev/git/project_8/pages/👨‍🏫_dashboard.py", line 10, in <module>
    import my_functions as my                # Custom module
  File "/home/user_n/Documents/Dev/git/project_8/utils/my_functions.py", line 11
    st.markdown(str_message)
                            ^
IndentationError: unindent does not match any outer indentation level
2024-07-09 17:23:03.651 Uncaught app exception
Traceback (most recent call last):
  File "/home/user_n/anaconda3/envs/env_proj_8/lib/python3.10/site-packages/streamlit/runtime/scriptrunner/script_runner.py", line 589, in _run_script
    exec(code, module.__dict__)
  File "/home/user_n/Documents/Dev/git/project_8/pages/👨‍🏫_dashboard.py", line 10, in <module>
    import my_functions as my                # Custom module
  File "/home/user_n/Documents/Dev/git/project_8/utils/my_functions.py", line 11
    st.markdown(str_message)
                            ^
IndentationError: unindent does not match any outer indentation level
2024-07-09 17:23:34.078 Uncaught app exception
Traceback (most recent call last):
  File "/home/user_n/anaconda3/envs/env_proj_8/lib/python3.10/site-packages/streamlit/runtime/scriptrunner/script_runner.py", line 589, in _run_script
    exec(code, module.__dict__)
  File "/home/user_n/Documents/Dev/git/project_8/pages/👨‍🏫_dashboard.py", line 10, in <module>
    import my_functions as my                # Custom module
  File "/home/user_n/Documents/Dev/git/project_8/utils/my_functions.py", line 11
    st.markdown(str_message)
                            ^
IndentationError: unindent does not match any outer indentation level
2024-07-09 17:24:15.818 Uncaught app exception
Traceback (most recent call last):
  File "/home/user_n/anaconda3/envs/env_proj_8/lib/python3.10/site-packages/streamlit/runtime/scriptrunner/script_runner.py", line 589, in _run_script
    exec(code, module.__dict__)
  File "/home/user_n/Documents/Dev/git/project_8/pages/👨‍🏫_dashboard.py", line 10, in <module>
    import my_functions as my                # Custom module
  File "/home/user_n/Documents/Dev/git/project_8/utils/my_functions.py", line 12
    with open('.log/streamlit_app.log', 'a') as f:             
                                                               ^
IndentationError: unindent does not match any outer indentation level
2024-07-09 17:24:30.705 Uncaught app exception
Traceback (most recent call last):
  File "/home/user_n/anaconda3/envs/env_proj_8/lib/python3.10/site-packages/streamlit/runtime/scriptrunner/script_runner.py", line 589, in _run_script
    exec(code, module.__dict__)
  File "/home/user_n/Documents/Dev/git/project_8/pages/👨‍🏫_dashboard.py", line 10, in <module>
    import my_functions as my                # Custom module
  File "/home/user_n/Documents/Dev/git/project_8/utils/my_functions.py", line 13
    print(str_message, file=f)
TabError: inconsistent use of tabs and spaces in indentation
2024-07-09 17:24:45.727 Uncaught app exception
Traceback (most recent call last):
  File "/home/user_n/anaconda3/envs/env_proj_8/lib/python3.10/site-packages/streamlit/runtime/scriptrunner/script_runner.py", line 589, in _run_script
    exec(code, module.__dict__)
  File "/home/user_n/Documents/Dev/git/project_8/pages/👨‍🏫_dashboard.py", line 17, in <module>
    my.debug(str_title + ' - Version 0.0.2')
  File "/home/user_n/Documents/Dev/git/project_8/utils/my_functions.py", line 12, in debug
    with open('.log/streamlit_app.log', 'a') as f:
FileNotFoundError: [Errno 2] No such file or directory: '.log/streamlit_app.log'
  % Total    % Received % Xferd  Average Speed   Time    Time     Time  Current
                                 Dload  Upload   Total   Spent    Left  Speed
  0     0    0     0    0     0      0      0 --:--:-- --:--:-- --:--:--     0  0     0    0     0    0     0      0      0 --:--:-- --:--:-- --:--:--     0
curl: (7) Failed to connect to localhost port 5677: Connection refused
2024-07-09 17:24:59.954 Uncaught app exception
Traceback (most recent call last):
  File "/home/user_n/anaconda3/envs/env_proj_8/lib/python3.10/site-packages/streamlit/runtime/scriptrunner/script_runner.py", line 589, in _run_script
    exec(code, module.__dict__)
  File "/home/user_n/Documents/Dev/git/project_8/pages/👨‍🏫_dashboard.py", line 65, in <module>
    float_1_score = my.get_li_scores(df_selected_record)[0]
  File "/home/user_n/Documents/Dev/git/project_8/utils/my_functions.py", line 60, in get_li_scores
    dict_predictions     = eval(str_dict_predictions) # {"predictions": [0]}
  File "<string>", line 0
    
SyntaxError: invalid syntax
2024-07-09 17:26:19.658 Uncaught app exception
Traceback (most recent call last):
  File "/home/user_n/anaconda3/envs/env_proj_8/lib/python3.10/site-packages/streamlit/runtime/scriptrunner/script_runner.py", line 589, in _run_script
    exec(code, module.__dict__)
  File "/home/user_n/Documents/Dev/git/project_8/pages/👨‍🏫_dashboard.py", line 10, in <module>
    import my_functions as my                # Custom module
  File "/home/user_n/Documents/Dev/git/project_8/utils/my_functions.py", line 58
    df_X_sample          = df_data_sample.drop('TARGET', axis='columns')
                                                                        ^
IndentationError: unindent does not match any outer indentation level
2024-07-09 17:26:37.247 Uncaught app exception
Traceback (most recent call last):
  File "/home/user_n/anaconda3/envs/env_proj_8/lib/python3.10/site-packages/streamlit/runtime/scriptrunner/script_runner.py", line 589, in _run_script
    exec(code, module.__dict__)
  File "/home/user_n/Documents/Dev/git/project_8/pages/👨‍🏫_dashboard.py", line 10, in <module>
    import my_functions as my                # Custom module
  File "/home/user_n/Documents/Dev/git/project_8/utils/my_functions.py", line 60
    	debug('str_dict_predictions=[' + ']')
    ^
TabError: inconsistent use of tabs and spaces in indentation
2024-07-09 17:27:24.148 Uncaught app exception
Traceback (most recent call last):
  File "/home/user_n/anaconda3/envs/env_proj_8/lib/python3.10/site-packages/streamlit/runtime/scriptrunner/script_runner.py", line 589, in _run_script
    exec(code, module.__dict__)
  File "/home/user_n/Documents/Dev/git/project_8/pages/👨‍🏫_dashboard.py", line 10, in <module>
    import my_functions as my                # Custom module
  File "/home/user_n/Documents/Dev/git/project_8/utils/my_functions.py", line 60
    	debug('str_dict_predictions=[' + ']')
    ^
TabError: inconsistent use of tabs and spaces in indentation
2024-07-09 17:28:06.581 Uncaught app exception
Traceback (most recent call last):
  File "/home/user_n/anaconda3/envs/env_proj_8/lib/python3.10/site-packages/streamlit/runtime/scriptrunner/script_runner.py", line 589, in _run_script
    exec(code, module.__dict__)
  File "/home/user_n/Documents/Dev/git/project_8/pages/👨‍🏫_dashboard.py", line 10, in <module>
    import my_functions as my                # Custom module
  File "/home/user_n/Documents/Dev/git/project_8/utils/my_functions.py", line 60
    	debug('str_dict_predictions=[' + ']')
    ^
TabError: inconsistent use of tabs and spaces in indentation
2024-07-09 17:28:45.392 Uncaught app exception
Traceback (most recent call last):
  File "/home/user_n/anaconda3/envs/env_proj_8/lib/python3.10/site-packages/streamlit/runtime/scriptrunner/script_runner.py", line 589, in _run_script
    exec(code, module.__dict__)
  File "/home/user_n/Documents/Dev/git/project_8/pages/👨‍🏫_dashboard.py", line 10, in <module>
    import my_functions as my                # Custom module
  File "/home/user_n/Documents/Dev/git/project_8/utils/my_functions.py", line 60
    	debug('str_dict_predictions=[' + ']')
    ^
TabError: inconsistent use of tabs and spaces in indentation
2024-07-09 17:29:23.897 Uncaught app exception
Traceback (most recent call last):
  File "/home/user_n/anaconda3/envs/env_proj_8/lib/python3.10/site-packages/streamlit/runtime/scriptrunner/script_runner.py", line 589, in _run_script
    exec(code, module.__dict__)
  File "/home/user_n/Documents/Dev/git/project_8/pages/👨‍🏫_dashboard.py", line 10, in <module>
    import my_functions as my                # Custom module
  File "/home/user_n/Documents/Dev/git/project_8/utils/my_functions.py", line 60
    	debug('str_dict_predictions=[' + ']')
    ^
TabError: inconsistent use of tabs and spaces in indentation
2024-07-09 17:30:16.956 Uncaught app exception
Traceback (most recent call last):
  File "/home/user_n/anaconda3/envs/env_proj_8/lib/python3.10/site-packages/streamlit/runtime/scriptrunner/script_runner.py", line 589, in _run_script
    exec(code, module.__dict__)
  File "/home/user_n/Documents/Dev/git/project_8/pages/👨‍🏫_dashboard.py", line 10, in <module>
    import my_functions as my                # Custom module
  File "/home/user_n/Documents/Dev/git/project_8/utils/my_functions.py", line 60
    	debug('str_dict_predictions=[' + ']')
    ^
TabError: inconsistent use of tabs and spaces in indentation
2024-07-09 17:30:40.085 Uncaught app exception
Traceback (most recent call last):
  File "/home/user_n/anaconda3/envs/env_proj_8/lib/python3.10/site-packages/streamlit/runtime/scriptrunner/script_runner.py", line 589, in _run_script
    exec(code, module.__dict__)
  File "/home/user_n/Documents/Dev/git/project_8/pages/👨‍🏫_dashboard.py", line 10, in <module>
    import my_functions as my                # Custom module
  File "/home/user_n/Documents/Dev/git/project_8/utils/my_functions.py", line 61
    	dict_predictions     = eval(str_dict_predictions) # {"predictions": [0]}
    ^
TabError: inconsistent use of tabs and spaces in indentation
  % Total    % Received % Xferd  Average Speed   Time    Time     Time  Current
                                 Dload  Upload   Total   Spent    Left  Speed
  0     0    0     0    0     0      0      0 --:--:-- --:--:-- --:--:--     0  0     0    0     0    0     0      0      0 --:--:-- --:--:-- --:--:--     0
curl: (7) Failed to connect to localhost port 5677: Connection refused
2024-07-09 17:34:32.075 Uncaught app exception
Traceback (most recent call last):
  File "/home/user_n/anaconda3/envs/env_proj_8/lib/python3.10/site-packages/streamlit/runtime/scriptrunner/script_runner.py", line 589, in _run_script
    exec(code, module.__dict__)
  File "/home/user_n/Documents/Dev/git/project_8/pages/👨‍🏫_dashboard.py", line 65, in <module>
    float_1_score = my.get_li_scores(df_selected_record)[0]
  File "/home/user_n/Documents/Dev/git/project_8/utils/my_functions.py", line 61, in get_li_scores
    dict_predictions	 = eval(str_dict_predictions) # {"predictions": [0]}
  File "<string>", line 0
    
SyntaxError: invalid syntax
  % Total    % Received % Xferd  Average Speed   Time    Time     Time  Current
                                 Dload  Upload   Total   Spent    Left  Speed
  0     0    0     0    0     0      0      0 --:--:-- --:--:-- --:--:--     0100   330  100    37  100   293    948   7512 --:--:-- --:--:-- --:--:--  8461
2024-07-09 17:37:14.838 Uncaught app exception
Traceback (most recent call last):
  File "/home/user_n/anaconda3/envs/env_proj_8/lib/python3.10/site-packages/streamlit/runtime/scriptrunner/script_runner.py", line 589, in _run_script
    exec(code, module.__dict__)
  File "/home/user_n/Documents/Dev/git/project_8/pages/👨‍🏫_dashboard.py", line 73, in <module>
    frame_left.plotly_chart(my.plot_gauge(100*float_1_score), use_container_width=True)
  File "/home/user_n/Documents/Dev/git/project_8/utils/my_functions.py", line 34, in plot_gauge
    gauge = go.Indicator(
NameError: name 'go' is not defined
  % Total    % Received % Xferd  Average Speed   Time    Time     Time  Current
                                 Dload  Upload   Total   Spent    Left  Speed
  0     0    0     0    0     0      0      0 --:--:-- --:--:-- --:--:--     0100   330  100    37  100   293    251   1993 --:--:-- --:--:-- --:--:--  2244
  % Total    % Received % Xferd  Average Speed   Time    Time     Time  Current
                                 Dload  Upload   Total   Spent    Left  Speed
  0     0    0     0    0     0      0      0 --:--:-- --:--:-- --:--:--     0100   330  100    37  100   293    770   6104 --:--:-- --:--:-- --:--:--  6875
  % Total    % Received % Xferd  Average Speed   Time    Time     Time  Current
                                 Dload  Upload   Total   Spent    Left  Speed
  0     0    0     0    0     0      0      0 --:--:-- --:--:-- --:--:--     0100   330  100    37  100   293   1088   8617 --:--:-- --:--:-- --:--:--  9705
  % Total    % Received % Xferd  Average Speed   Time    Time     Time  Current
                                 Dload  Upload   Total   Spent    Left  Speed
  0     0    0     0    0     0      0      0 --:--:-- --:--:-- --:--:--     0100   330  100    37  100   293   1275  10103 --:--:-- --:--:-- --:--:-- 11785
  % Total    % Received % Xferd  Average Speed   Time    Time     Time  Current
                                 Dload  Upload   Total   Spent    Left  Speed
  0     0    0     0    0     0      0      0 --:--:-- --:--:-- --:--:--     0100   330  100    37  100   293    560   4439 --:--:-- --:--:-- --:--:--  5000
  % Total    % Received % Xferd  Average Speed   Time    Time     Time  Current
                                 Dload  Upload   Total   Spent    Left  Speed
  0     0    0     0    0     0      0      0 --:--:-- --:--:-- --:--:--     0100   330  100    37  100   293   1088   8617 --:--:-- --:--:-- --:--:--  9705
  % Total    % Received % Xferd  Average Speed   Time    Time     Time  Current
                                 Dload  Upload   Total   Spent    Left  Speed
  0     0    0     0    0     0      0      0 --:--:-- --:--:-- --:--:--     0100   331  100    37  100   294   1057   8400 --:--:-- --:--:-- --:--:--  9457
  % Total    % Received % Xferd  Average Speed   Time    Time     Time  Current
                                 Dload  Upload   Total   Spent    Left  Speed
  0     0    0     0    0     0      0      0 --:--:-- --:--:-- --:--:--     0100   330  100    37  100   293   1057   8371 --:--:-- --:--:-- --:--:--  9428
  % Total    % Received % Xferd  Average Speed   Time    Time     Time  Current
                                 Dload  Upload   Total   Spent    Left  Speed
  0     0    0     0    0     0      0      0 --:--:-- --:--:-- --:--:--     0100   330  100    37  100   293   1681  13318 --:--:-- --:--:-- --:--:-- 15000
2024-07-09 18:57:12.652 Uncaught app exception
Traceback (most recent call last):
  File "/home/user_n/anaconda3/envs/env_proj_8/lib/python3.10/site-packages/streamlit/runtime/scriptrunner/script_runner.py", line 589, in _run_script
    exec(code, module.__dict__)
  File "/home/user_n/Documents/Dev/git/project_8/pages/👨‍🏫_dashboard.py", line 77, in <module>
    np_shap_values = np.load(dir_out + 'shap_values.npy')
NameError: name 'dir_out' is not defined
  % Total    % Received % Xferd  Average Speed   Time    Time     Time  Current
                                 Dload  Upload   Total   Spent    Left  Speed
  0     0    0     0    0     0      0      0 --:--:-- --:--:-- --:--:--     0100   330  100    37  100   293    925   7325 --:--:-- --:--:-- --:--:--  8250
2024-07-09 18:57:33.600 Uncaught app exception
Traceback (most recent call last):
  File "/home/user_n/anaconda3/envs/env_proj_8/lib/python3.10/site-packages/streamlit/runtime/scriptrunner/script_runner.py", line 589, in _run_script
    exec(code, module.__dict__)
  File "/home/user_n/Documents/Dev/git/project_8/pages/👨‍🏫_dashboard.py", line 79, in <module>
    graph_violins = shap.summary_plot(np_shap_values, df_X)
NameError: name 'df_X' is not defined
  % Total    % Received % Xferd  Average Speed   Time    Time     Time  Current
                                 Dload  Upload   Total   Spent    Left  Speed
  0     0    0     0    0     0      0      0 --:--:-- --:--:-- --:--:--     0100   330  100    37  100   293    711   5634 --:--:-- --:--:-- --:--:--  6346
2024-07-09 18:59:23.444 Uncaught app exception
Traceback (most recent call last):
  File "/home/user_n/anaconda3/envs/env_proj_8/lib/python3.10/site-packages/streamlit/runtime/scriptrunner/script_runner.py", line 589, in _run_script
    exec(code, module.__dict__)
  File "/home/user_n/Documents/Dev/git/project_8/pages/👨‍🏫_dashboard.py", line 80, in <module>
    graph_violins = shap.summary_plot(np_shap_values, df_X)
  File "/home/user_n/anaconda3/envs/env_proj_8/lib/python3.10/site-packages/shap/plots/_beeswarm.py", line 543, in summary_legacy
    assert num_features == features.shape[1], shape_msg
AssertionError: The shape of the shap_values matrix does not match the shape of the provided data matrix.
2024-07-09 18:59:49.173 Uncaught app exception
Traceback (most recent call last):
  File "/home/user_n/anaconda3/envs/env_proj_8/lib/python3.10/site-packages/streamlit/runtime/scriptrunner/script_runner.py", line 589, in _run_script
    exec(code, module.__dict__)
  File "/home/user_n/Documents/Dev/git/project_8/pages/👨‍🏫_dashboard.py", line 31, in <module>
    df_X      = my.load_data(path_X)
TypeError: load_data() missing 1 required positional argument: 'nb_rows'
  % Total    % Received % Xferd  Average Speed   Time    Time     Time  Current
                                 Dload  Upload   Total   Spent    Left  Speed
  0     0    0     0    0     0      0      0 --:--:-- --:--:-- --:--:--     0100   330  100    37  100   293   1608  12739 --:--:-- --:--:-- --:--:-- 14347
2024-07-09 19:02:33.451 Uncaught app exception
Traceback (most recent call last):
  File "/home/user_n/anaconda3/envs/env_proj_8/lib/python3.10/site-packages/streamlit/runtime/scriptrunner/script_runner.py", line 589, in _run_script
    exec(code, module.__dict__)
  File "/home/user_n/Documents/Dev/git/project_8/pages/👨‍🏫_dashboard.py", line 80, in <module>
    graph_violins = shap.summary_plot(np_shap_values, df_X)
  File "/home/user_n/anaconda3/envs/env_proj_8/lib/python3.10/site-packages/shap/plots/_beeswarm.py", line 543, in summary_legacy
    assert num_features == features.shape[1], shape_msg
AssertionError: The shape of the shap_values matrix does not match the shape of the provided data matrix.
2024-07-09 19:07:27.893 Uncaught app exception
Traceback (most recent call last):
  File "/home/user_n/anaconda3/envs/env_proj_8/lib/python3.10/site-packages/streamlit/runtime/scriptrunner/script_runner.py", line 589, in _run_script
    exec(code, module.__dict__)
  File "/home/user_n/Documents/Dev/git/project_8/pages/👨‍🏫_dashboard.py", line 11, in <module>
    import my_functions as my                # Custom module
  File "/home/user_n/Documents/Dev/git/project_8/utils/my_functions.py", line 92
    def get_li_features(path)
                             ^
SyntaxError: expected ':'
2024-07-09 19:07:45.195 Uncaught app exception
Traceback (most recent call last):
  File "/home/user_n/anaconda3/envs/env_proj_8/lib/python3.10/site-packages/streamlit/runtime/scriptrunner/script_runner.py", line 589, in _run_script
    exec(code, module.__dict__)
  File "/home/user_n/Documents/Dev/git/project_8/pages/👨‍🏫_dashboard.py", line 31, in <module>
    df_X      = my.load_data(path_X)[get_li_features(dir_in + 'li_features.txt')]
NameError: name 'get_li_features' is not defined
  % Total    % Received % Xferd  Average Speed   Time    Time     Time  Current
                                 Dload  Upload   Total   Spent    Left  Speed
  0     0    0     0    0     0      0      0 --:--:-- --:--:-- --:--:--     0100   330  100    37  100   293   1761  13952 --:--:-- --:--:-- --:--:-- 15714
/home/user_n/anaconda3/envs/env_proj_8/lib/python3.10/site-packages/shap/plots/_beeswarm.py:952: UserWarning:

FigureCanvasAgg is non-interactive, and thus cannot be shown

2024-07-09 19:08:40.803 Uncaught app exception
Traceback (most recent call last):
  File "/home/user_n/anaconda3/envs/env_proj_8/lib/python3.10/site-packages/streamlit/runtime/scriptrunner/script_runner.py", line 589, in _run_script
    exec(code, module.__dict__)
  File "/home/user_n/Documents/Dev/git/project_8/pages/👨‍🏫_dashboard.py", line 83, in <module>
    st.pyplot(shap.plots.force(graph_violins, matplotlib=True))
  File "/home/user_n/anaconda3/envs/env_proj_8/lib/python3.10/site-packages/shap/plots/_force.py", line 138, in force
    return visualize(shap_values)
  File "/home/user_n/anaconda3/envs/env_proj_8/lib/python3.10/site-packages/shap/plots/_force.py", line 428, in visualize
    raise ValueError("visualize() can only display Explanation objects (or arrays of them)!")
ValueError: visualize() can only display Explanation objects (or arrays of them)!
  % Total    % Received % Xferd  Average Speed   Time    Time     Time  Current
                                 Dload  Upload   Total   Spent    Left  Speed
  0     0    0     0    0     0      0      0 --:--:-- --:--:-- --:--:--     0100   330  100    37  100   293   1761  13952 --:--:-- --:--:-- --:--:-- 15714
/home/user_n/anaconda3/envs/env_proj_8/lib/python3.10/site-packages/shap/plots/_beeswarm.py:952: UserWarning:

FigureCanvasAgg is non-interactive, and thus cannot be shown

2024-07-09 19:09:46.803 Uncaught app exception
Traceback (most recent call last):
  File "/home/user_n/anaconda3/envs/env_proj_8/lib/python3.10/site-packages/streamlit/runtime/scriptrunner/script_runner.py", line 589, in _run_script
    exec(code, module.__dict__)
  File "/home/user_n/Documents/Dev/git/project_8/pages/👨‍🏫_dashboard.py", line 84, in <module>
    shap.force_plot(graph_violins, matplotlib=True)
  File "/home/user_n/anaconda3/envs/env_proj_8/lib/python3.10/site-packages/shap/plots/_force.py", line 138, in force
    return visualize(shap_values)
  File "/home/user_n/anaconda3/envs/env_proj_8/lib/python3.10/site-packages/shap/plots/_force.py", line 428, in visualize
    raise ValueError("visualize() can only display Explanation objects (or arrays of them)!")
ValueError: visualize() can only display Explanation objects (or arrays of them)!
  % Total    % Received % Xferd  Average Speed   Time    Time     Time  Current
                                 Dload  Upload   Total   Spent    Left  Speed
  0     0    0     0    0     0      0      0 --:--:-- --:--:-- --:--:--     0100   330  100    37  100   293    840   6659 --:--:-- --:--:-- --:--:--  7674
/home/user_n/anaconda3/envs/env_proj_8/lib/python3.10/site-packages/shap/plots/_beeswarm.py:952: UserWarning:

FigureCanvasAgg is non-interactive, and thus cannot be shown

2024-07-09 19:10:19.233 Uncaught app exception
Traceback (most recent call last):
  File "/home/user_n/anaconda3/envs/env_proj_8/lib/python3.10/site-packages/streamlit/runtime/scriptrunner/script_runner.py", line 589, in _run_script
    exec(code, module.__dict__)
  File "/home/user_n/Documents/Dev/git/project_8/pages/👨‍🏫_dashboard.py", line 82, in <module>
    st.write(shap.force_plot(graph_violins, matplotlib=True), unsafe_allow_html=True)
  File "/home/user_n/anaconda3/envs/env_proj_8/lib/python3.10/site-packages/shap/plots/_force.py", line 138, in force
    return visualize(shap_values)
  File "/home/user_n/anaconda3/envs/env_proj_8/lib/python3.10/site-packages/shap/plots/_force.py", line 428, in visualize
    raise ValueError("visualize() can only display Explanation objects (or arrays of them)!")
ValueError: visualize() can only display Explanation objects (or arrays of them)!
  % Total    % Received % Xferd  Average Speed   Time    Time     Time  Current
                                 Dload  Upload   Total   Spent    Left  Speed
  0     0    0     0    0     0      0      0 --:--:-- --:--:-- --:--:--     0100   293    0     0  100   293      0  11720 --:--:-- --:--:-- --:--:-- 11720100   330  100    37  100   293   1423  11269 --:--:-- --:--:-- --:--:-- 12222
/home/user_n/anaconda3/envs/env_proj_8/lib/python3.10/site-packages/shap/plots/_beeswarm.py:952: UserWarning:

FigureCanvasAgg is non-interactive, and thus cannot be shown

2024-07-09 19:17:29.614 Uncaught app exception
Traceback (most recent call last):
  File "/home/user_n/anaconda3/envs/env_proj_8/lib/python3.10/site-packages/streamlit/runtime/scriptrunner/script_runner.py", line 589, in _run_script
    exec(code, module.__dict__)
  File "/home/user_n/Documents/Dev/git/project_8/pages/👨‍🏫_dashboard.py", line 82, in <module>
    st.write(shap.force_plot(graph_violins, matplotlib=True), unsafe_allow_html=True)
  File "/home/user_n/anaconda3/envs/env_proj_8/lib/python3.10/site-packages/shap/plots/_force.py", line 138, in force
    return visualize(shap_values)
  File "/home/user_n/anaconda3/envs/env_proj_8/lib/python3.10/site-packages/shap/plots/_force.py", line 428, in visualize
    raise ValueError("visualize() can only display Explanation objects (or arrays of them)!")
ValueError: visualize() can only display Explanation objects (or arrays of them)!
  % Total    % Received % Xferd  Average Speed   Time    Time     Time  Current
                                 Dload  Upload   Total   Spent    Left  Speed
  0     0    0     0    0     0      0      0 --:--:-- --:--:-- --:--:--     0100   330  100    37  100   293   1233   9766 --:--:-- --:--:-- --:--:-- 11000
/home/user_n/anaconda3/envs/env_proj_8/lib/python3.10/site-packages/shap/plots/_beeswarm.py:952: UserWarning:

FigureCanvasAgg is non-interactive, and thus cannot be shown

  % Total    % Received % Xferd  Average Speed   Time    Time     Time  Current
                                 Dload  Upload   Total   Spent    Left  Speed
  0     0    0     0    0     0      0      0 --:--:-- --:--:-- --:--:--     0100   330  100    37  100   293   1027   8138 --:--:-- --:--:-- --:--:--  9166
2024-07-09 19:21:03.326 Uncaught app exception
Traceback (most recent call last):
  File "/home/user_n/anaconda3/envs/env_proj_8/lib/python3.10/site-packages/streamlit/runtime/scriptrunner/script_runner.py", line 589, in _run_script
    exec(code, module.__dict__)
  File "/home/user_n/Documents/Dev/git/project_8/pages/👨‍🏫_dashboard.py", line 81, in <module>
    fig, ax = plt.subplots()
NameError: name 'plt' is not defined
  % Total    % Received % Xferd  Average Speed   Time    Time     Time  Current
                                 Dload  Upload   Total   Spent    Left  Speed
  0     0    0     0    0     0      0      0 --:--:-- --:--:-- --:--:--     0100   330  100    37  100   293    725   5745 --:--:-- --:--:-- --:--:--  6470
2024-07-09 19:21:20.994 Uncaught app exception
Traceback (most recent call last):
  File "/home/user_n/anaconda3/envs/env_proj_8/lib/python3.10/site-packages/streamlit/runtime/scriptrunner/script_runner.py", line 589, in _run_script
    exec(code, module.__dict__)
  File "/home/user_n/Documents/Dev/git/project_8/pages/👨‍🏫_dashboard.py", line 81, in <module>
    fig, ax = plt.subplots()
NameError: name 'plt' is not defined
  % Total    % Received % Xferd  Average Speed   Time    Time     Time  Current
                                 Dload  Upload   Total   Spent    Left  Speed
  0     0    0     0    0     0      0      0 --:--:-- --:--:-- --:--:--     0100   330  100    37  100   293   1088   8617 --:--:-- --:--:-- --:--:--  9705
/home/user_n/anaconda3/envs/env_proj_8/lib/python3.10/site-packages/shap/plots/_beeswarm.py:952: UserWarning:

FigureCanvasAgg is non-interactive, and thus cannot be shown

  % Total    % Received % Xferd  Average Speed   Time    Time     Time  Current
                                 Dload  Upload   Total   Spent    Left  Speed
  0     0    0     0    0     0      0      0 --:--:-- --:--:-- --:--:--     0100   330  100    37  100   293   1321  10464 --:--:-- --:--:-- --:--:-- 11785
/home/user_n/anaconda3/envs/env_proj_8/lib/python3.10/site-packages/shap/plots/_beeswarm.py:952: UserWarning:

FigureCanvasAgg is non-interactive, and thus cannot be shown

  % Total    % Received % Xferd  Average Speed   Time    Time     Time  Current
                                 Dload  Upload   Total   Spent    Left  Speed
  0     0    0     0    0     0      0      0 --:--:-- --:--:-- --:--:--     0100   330  100    37  100   293   1850  14650 --:--:-- --:--:-- --:--:-- 16500
/home/user_n/anaconda3/envs/env_proj_8/lib/python3.10/site-packages/shap/plots/_beeswarm.py:952: UserWarning:

FigureCanvasAgg is non-interactive, and thus cannot be shown

  % Total    % Received % Xferd  Average Speed   Time    Time     Time  Current
                                 Dload  Upload   Total   Spent    Left  Speed
  0     0    0     0    0     0      0      0 --:--:-- --:--:-- --:--:--     0100   330  100    37  100   293   1608  12739 --:--:-- --:--:-- --:--:-- 14347
/home/user_n/anaconda3/envs/env_proj_8/lib/python3.10/site-packages/shap/plots/_beeswarm.py:952: UserWarning:

FigureCanvasAgg is non-interactive, and thus cannot be shown

  % Total    % Received % Xferd  Average Speed   Time    Time     Time  Current
                                 Dload  Upload   Total   Spent    Left  Speed
  0     0    0     0    0     0      0      0 --:--:-- --:--:-- --:--:--     0100   330  100    37  100   293   2846  22538 --:--:-- --:--:-- --:--:-- 25384
/home/user_n/anaconda3/envs/env_proj_8/lib/python3.10/site-packages/shap/plots/_beeswarm.py:952: UserWarning:

FigureCanvasAgg is non-interactive, and thus cannot be shown

  % Total    % Received % Xferd  Average Speed   Time    Time     Time  Current
                                 Dload  Upload   Total   Spent    Left  Speed
  0     0    0     0    0     0      0      0 --:--:-- --:--:-- --:--:--     0100   330  100    37  100   293    698   5528 --:--:-- --:--:-- --:--:--  6226
/home/user_n/anaconda3/envs/env_proj_8/lib/python3.10/site-packages/shap/plots/_beeswarm.py:952: UserWarning:

FigureCanvasAgg is non-interactive, and thus cannot be shown

  % Total    % Received % Xferd  Average Speed   Time    Time     Time  Current
                                 Dload  Upload   Total   Spent    Left  Speed
  0     0    0     0    0     0      0      0 --:--:-- --:--:-- --:--:--     0100   330  100    37  100   293    698   5528 --:--:-- --:--:-- --:--:--  6226
/home/user_n/anaconda3/envs/env_proj_8/lib/python3.10/site-packages/shap/plots/_beeswarm.py:952: UserWarning:

FigureCanvasAgg is non-interactive, and thus cannot be shown

  % Total    % Received % Xferd  Average Speed   Time    Time     Time  Current
                                 Dload  Upload   Total   Spent    Left  Speed
  0     0    0     0    0     0      0      0 --:--:-- --:--:-- --:--:--     0100   330  100    37  100   293   1275  10103 --:--:-- --:--:-- --:--:-- 11379
  % Total    % Received % Xferd  Average Speed   Time    Time     Time  Current
                                 Dload  Upload   Total   Spent    Left  Speed
  0     0    0     0    0     0      0      0 --:--:-- --:--:-- --:--:--     0100   330  100    37  100   293   1947  15421 --:--:-- --:--:-- --:--:-- 18333
  % Total    % Received % Xferd  Average Speed   Time    Time     Time  Current
                                 Dload  Upload   Total   Spent    Left  Speed
  0     0    0     0    0     0      0      0 --:--:-- --:--:-- --:--:--     0100   330  100    37  100   293   1608  12739 --:--:-- --:--:-- --:--:-- 15000
2024-07-09 19:37:08.173 Uncaught app exception
Traceback (most recent call last):
  File "/home/user_n/anaconda3/envs/env_proj_8/lib/python3.10/site-packages/streamlit/runtime/scriptrunner/script_runner.py", line 589, in _run_script
    exec(code, module.__dict__)
  File "/home/user_n/Documents/Dev/git/project_8/pages/👨‍🏫_dashboard.py", line 88, in <module>
    plot_shap_violins(dir_out, df_X.rename(columns=li_new_features))
  File "/home/user_n/anaconda3/envs/env_proj_8/lib/python3.10/site-packages/pandas/core/frame.py", line 5767, in rename
    return super()._rename(
  File "/home/user_n/anaconda3/envs/env_proj_8/lib/python3.10/site-packages/pandas/core/generic.py", line 1132, in _rename
    new_index = ax._transform_index(f, level=level)
  File "/home/user_n/anaconda3/envs/env_proj_8/lib/python3.10/site-packages/pandas/core/indexes/base.py", line 6537, in _transform_index
    items = [func(x) for x in self]
  File "/home/user_n/anaconda3/envs/env_proj_8/lib/python3.10/site-packages/pandas/core/indexes/base.py", line 6537, in <listcomp>
    items = [func(x) for x in self]
TypeError: 'list' object is not callable
  % Total    % Received % Xferd  Average Speed   Time    Time     Time  Current
                                 Dload  Upload   Total   Spent    Left  Speed
  0     0    0     0    0     0      0      0 --:--:-- --:--:-- --:--:--     0100   330  100    37  100   293   1423  11269 --:--:-- --:--:-- --:--:-- 12692
/home/user_n/anaconda3/envs/env_proj_8/lib/python3.10/site-packages/shap/plots/_beeswarm.py:952: UserWarning:

FigureCanvasAgg is non-interactive, and thus cannot be shown

  % Total    % Received % Xferd  Average Speed   Time    Time     Time  Current
                                 Dload  Upload   Total   Spent    Left  Speed
  0     0    0     0    0     0      0      0 --:--:-- --:--:-- --:--:--     0100   330  100    37  100   293   1480  11720 --:--:-- --:--:-- --:--:-- 13200
/home/user_n/anaconda3/envs/env_proj_8/lib/python3.10/site-packages/shap/plots/_beeswarm.py:952: UserWarning:

FigureCanvasAgg is non-interactive, and thus cannot be shown

  % Total    % Received % Xferd  Average Speed   Time    Time     Time  Current
                                 Dload  Upload   Total   Spent    Left  Speed
  0     0    0     0    0     0      0      0 --:--:-- --:--:-- --:--:--     0100   330  100    37  100   293   1233   9766 --:--:-- --:--:-- --:--:-- 11000
/home/user_n/anaconda3/envs/env_proj_8/lib/python3.10/site-packages/shap/plots/_beeswarm.py:952: UserWarning:

FigureCanvasAgg is non-interactive, and thus cannot be shown

  % Total    % Received % Xferd  Average Speed   Time    Time     Time  Current
                                 Dload  Upload   Total   Spent    Left  Speed
  0     0    0     0    0     0      0      0 --:--:-- --:--:-- --:--:--     0100   330  100    37  100   293   1608  12739 --:--:-- --:--:-- --:--:-- 14347
  % Total    % Received % Xferd  Average Speed   Time    Time     Time  Current
                                 Dload  Upload   Total   Spent    Left  Speed
  0     0    0     0    0     0      0      0 --:--:-- --:--:-- --:--:--     0100   330  100    37  100   293    755   5979 --:--:-- --:--:-- --:--:--  6734
/home/user_n/anaconda3/envs/env_proj_8/lib/python3.10/site-packages/shap/plots/_beeswarm.py:952: UserWarning:

FigureCanvasAgg is non-interactive, and thus cannot be shown

  % Total    % Received % Xferd  Average Speed   Time    Time     Time  Current
                                 Dload  Upload   Total   Spent    Left  Speed
  0     0    0     0    0     0      0      0 --:--:-- --:--:-- --:--:--     0100   330  100    37  100   293   2055  16277 --:--:-- --:--:-- --:--:-- 18333
/home/user_n/anaconda3/envs/env_proj_8/lib/python3.10/site-packages/shap/plots/_beeswarm.py:952: UserWarning:

FigureCanvasAgg is non-interactive, and thus cannot be shown

  % Total    % Received % Xferd  Average Speed   Time    Time     Time  Current
                                 Dload  Upload   Total   Spent    Left  Speed
  0     0    0     0    0     0      0      0 --:--:-- --:--:-- --:--:--     0100   330  100    37  100   293   1480  11720 --:--:-- --:--:-- --:--:-- 13750
/home/user_n/anaconda3/envs/env_proj_8/lib/python3.10/site-packages/shap/plots/_beeswarm.py:952: UserWarning:

FigureCanvasAgg is non-interactive, and thus cannot be shown

  % Total    % Received % Xferd  Average Speed   Time    Time     Time  Current
                                 Dload  Upload   Total   Spent    Left  Speed
  0     0    0     0    0     0      0      0 --:--:-- --:--:-- --:--:--     0100   330  100    37  100   293    787   6234 --:--:-- --:--:-- --:--:--  7021
/home/user_n/anaconda3/envs/env_proj_8/lib/python3.10/site-packages/shap/plots/_beeswarm.py:952: UserWarning:

FigureCanvasAgg is non-interactive, and thus cannot be shown

  % Total    % Received % Xferd  Average Speed   Time    Time     Time  Current
                                 Dload  Upload   Total   Spent    Left  Speed
  0     0    0     0    0     0      0      0 --:--:-- --:--:-- --:--:--     0100   330  100    37  100   293   1193   9451 --:--:-- --:--:-- --:--:-- 10645
/home/user_n/anaconda3/envs/env_proj_8/lib/python3.10/site-packages/shap/plots/_beeswarm.py:952: UserWarning:

FigureCanvasAgg is non-interactive, and thus cannot be shown

  % Total    % Received % Xferd  Average Speed   Time    Time     Time  Current
                                 Dload  Upload   Total   Spent    Left  Speed
  0     0    0     0    0     0      0      0 --:--:-- --:--:-- --:--:--     0100   330  100    37  100   293    948   7512 --:--:-- --:--:-- --:--:--  8461
/home/user_n/anaconda3/envs/env_proj_8/lib/python3.10/site-packages/shap/plots/_beeswarm.py:952: UserWarning:

FigureCanvasAgg is non-interactive, and thus cannot be shown

  % Total    % Received % Xferd  Average Speed   Time    Time     Time  Current
                                 Dload  Upload   Total   Spent    Left  Speed
  0     0    0     0    0     0      0      0 --:--:-- --:--:-- --:--:--     0100   330  100    37  100   293   2846  22538 --:--:-- --:--:-- --:--:-- 25384
/home/user_n/anaconda3/envs/env_proj_8/lib/python3.10/site-packages/shap/plots/_beeswarm.py:952: UserWarning:

FigureCanvasAgg is non-interactive, and thus cannot be shown

  % Total    % Received % Xferd  Average Speed   Time    Time     Time  Current
                                 Dload  Upload   Total   Spent    Left  Speed
  0     0    0     0    0     0      0      0 --:--:-- --:--:-- --:--:--     0100   330  100    37  100   293    711   5634 --:--:-- --:--:-- --:--:--  6346
/home/user_n/anaconda3/envs/env_proj_8/lib/python3.10/site-packages/shap/plots/_beeswarm.py:952: UserWarning:

FigureCanvasAgg is non-interactive, and thus cannot be shown

  % Total    % Received % Xferd  Average Speed   Time    Time     Time  Current
                                 Dload  Upload   Total   Spent    Left  Speed
  0     0    0     0    0     0      0      0 --:--:-- --:--:-- --:--:--     0100   330  100    37  100   293   1275  10103 --:--:-- --:--:-- --:--:-- 11379
/home/user_n/anaconda3/envs/env_proj_8/lib/python3.10/site-packages/shap/plots/_beeswarm.py:952: UserWarning:

FigureCanvasAgg is non-interactive, and thus cannot be shown

  % Total    % Received % Xferd  Average Speed   Time    Time     Time  Current
                                 Dload  Upload   Total   Spent    Left  Speed
  0     0    0     0    0     0      0      0 --:--:-- --:--:-- --:--:--     0100   330  100    37  100   293   1088   8617 --:--:-- --:--:-- --:--:--  9705
/home/user_n/anaconda3/envs/env_proj_8/lib/python3.10/site-packages/shap/plots/_beeswarm.py:952: UserWarning:

FigureCanvasAgg is non-interactive, and thus cannot be shown

  % Total    % Received % Xferd  Average Speed   Time    Time     Time  Current
                                 Dload  Upload   Total   Spent    Left  Speed
  0     0    0     0    0     0      0      0 --:--:-- --:--:-- --:--:--     0100   330  100    37  100   293   1275  10103 --:--:-- --:--:-- --:--:-- 11379
/home/user_n/anaconda3/envs/env_proj_8/lib/python3.10/site-packages/shap/plots/_beeswarm.py:952: UserWarning:

FigureCanvasAgg is non-interactive, and thus cannot be shown

  % Total    % Received % Xferd  Average Speed   Time    Time     Time  Current
                                 Dload  Upload   Total   Spent    Left  Speed
  0     0    0     0    0     0      0      0 --:--:-- --:--:-- --:--:--     0100   330  100    37  100   293   1233   9766 --:--:-- --:--:-- --:--:-- 11000
/home/user_n/anaconda3/envs/env_proj_8/lib/python3.10/site-packages/shap/plots/_beeswarm.py:952: UserWarning:

FigureCanvasAgg is non-interactive, and thus cannot be shown

  % Total    % Received % Xferd  Average Speed   Time    Time     Time  Current
                                 Dload  Upload   Total   Spent    Left  Speed
  0     0    0     0    0     0      0      0 --:--:-- --:--:-- --:--:--     0100   330  100    37  100   293   2846  22538 --:--:-- --:--:-- --:--:-- 25384
2024-07-09 20:15:32.783 Uncaught app exception
Traceback (most recent call last):
  File "/home/user_n/anaconda3/envs/env_proj_8/lib/python3.10/site-packages/streamlit/runtime/scriptrunner/script_runner.py", line 589, in _run_script
    exec(code, module.__dict__)
  File "/home/user_n/Documents/Dev/git/project_8/pages/👨‍🏫_dashboard.py", line 81, in <module>
    my.plot_shap_violins(dir_out, df_X, li_new_features)
  File "/home/user_n/Documents/Dev/git/project_8/utils/my_functions.py", line 101, in plot_shap_violins
    np_shap_values = np.load(dir_shap + 'shap_values.npy')
NameError: name 'np' is not defined
  % Total    % Received % Xferd  Average Speed   Time    Time     Time  Current
                                 Dload  Upload   Total   Spent    Left  Speed
  0     0    0     0    0     0      0      0 --:--:-- --:--:-- --:--:--     0100   330  100    37  100   293   2055  16277 --:--:-- --:--:-- --:--:-- 18333
2024-07-09 20:16:48.865 Uncaught app exception
Traceback (most recent call last):
  File "/home/user_n/anaconda3/envs/env_proj_8/lib/python3.10/site-packages/streamlit/runtime/scriptrunner/script_runner.py", line 589, in _run_script
    exec(code, module.__dict__)
  File "/home/user_n/Documents/Dev/git/project_8/pages/👨‍🏫_dashboard.py", line 81, in <module>
    my.plot_shap_violins(dir_out, df_X, li_new_features)
  File "/home/user_n/Documents/Dev/git/project_8/utils/my_functions.py", line 103, in plot_shap_violins
    fig, ax = plt.subplots(figsize=(3, 2))
NameError: name 'plt' is not defined
  % Total    % Received % Xferd  Average Speed   Time    Time     Time  Current
                                 Dload  Upload   Total   Spent    Left  Speed
  0     0    0     0    0     0      0      0 --:--:-- --:--:-- --:--:--     0100   330  100    37  100   293   1121   8878 --:--:-- --:--:-- --:--:-- 10000
/home/user_n/anaconda3/envs/env_proj_8/lib/python3.10/site-packages/shap/plots/_beeswarm.py:952: UserWarning:

FigureCanvasAgg is non-interactive, and thus cannot be shown

2024-07-09 20:17:22.181 Uncaught app exception
Traceback (most recent call last):
  File "/home/user_n/anaconda3/envs/env_proj_8/lib/python3.10/site-packages/streamlit/runtime/scriptrunner/script_runner.py", line 589, in _run_script
    exec(code, module.__dict__)
  File "/home/user_n/Documents/Dev/git/project_8/pages/👨‍🏫_dashboard.py", line 81, in <module>
    my.plot_shap_violins(dir_out, df_X, li_new_features)
  File "/home/user_n/Documents/Dev/git/project_8/utils/my_functions.py", line 106, in plot_shap_violins
    frame_right.pyplot(fig)
NameError: name 'frame_right' is not defined
  % Total    % Received % Xferd  Average Speed   Time    Time     Time  Current
                                 Dload  Upload   Total   Spent    Left  Speed
  0     0    0     0    0     0      0      0 --:--:-- --:--:-- --:--:--     0100   330  100    37  100   293   1088   8617 --:--:-- --:--:-- --:--:--  9705
/home/user_n/anaconda3/envs/env_proj_8/lib/python3.10/site-packages/shap/plots/_beeswarm.py:952: UserWarning:

FigureCanvasAgg is non-interactive, and thus cannot be shown

  % Total    % Received % Xferd  Average Speed   Time    Time     Time  Current
                                 Dload  Upload   Total   Spent    Left  Speed
  0     0    0     0    0     0      0      0 --:--:-- --:--:-- --:--:--     0100   330  100    37  100   293   1541  12208 --:--:-- --:--:-- --:--:-- 13750
/home/user_n/anaconda3/envs/env_proj_8/lib/python3.10/site-packages/shap/plots/_beeswarm.py:952: UserWarning:

FigureCanvasAgg is non-interactive, and thus cannot be shown

/home/user_n/anaconda3/envs/env_proj_8/lib/python3.10/site-packages/shap/plots/_beeswarm.py:952: UserWarning:

FigureCanvasAgg is non-interactive, and thus cannot be shown

  % Total    % Received % Xferd  Average Speed   Time    Time     Time  Current
                                 Dload  Upload   Total   Spent    Left  Speed
  0     0    0     0    0     0      0      0 --:--:-- --:--:-- --:--:--     0100   330  100    37  100   293    711   5634 --:--:-- --:--:-- --:--:--  6346
/home/user_n/anaconda3/envs/env_proj_8/lib/python3.10/site-packages/shap/plots/_beeswarm.py:952: UserWarning:

FigureCanvasAgg is non-interactive, and thus cannot be shown

/home/user_n/anaconda3/envs/env_proj_8/lib/python3.10/site-packages/shap/plots/_beeswarm.py:952: UserWarning:

FigureCanvasAgg is non-interactive, and thus cannot be shown

  % Total    % Received % Xferd  Average Speed   Time    Time     Time  Current
                                 Dload  Upload   Total   Spent    Left  Speed
  0     0    0     0    0     0      0      0 --:--:-- --:--:-- --:--:--     0100   330  100    37  100   293    725   5745 --:--:-- --:--:-- --:--:--  6470
2024-07-09 20:38:09.446 Uncaught app exception
Traceback (most recent call last):
  File "/home/user_n/anaconda3/envs/env_proj_8/lib/python3.10/site-packages/streamlit/runtime/caching/hashing.py", line 552, in _to_bytes
    reduce_data = obj.__reduce__()
  File "/home/user_n/anaconda3/envs/env_proj_8/lib/python3.10/copyreg.py", line 92, in _reduce_ex
    dict = getstate()
  File "/home/user_n/anaconda3/envs/env_proj_8/lib/python3.10/site-packages/streamlit/delta_generator.py", line 345, in wrapper
    raise StreamlitAPIException(message)
streamlit.errors.StreamlitAPIException: `__getstate__()` is not a valid Streamlit command.

The above exception was the direct cause of the following exception:

Traceback (most recent call last):
  File "/home/user_n/anaconda3/envs/env_proj_8/lib/python3.10/site-packages/streamlit/runtime/caching/cache_utils.py", line 409, in _make_value_key
    update_hash(
  File "/home/user_n/anaconda3/envs/env_proj_8/lib/python3.10/site-packages/streamlit/runtime/caching/hashing.py", line 158, in update_hash
    ch.update(hasher, val)
  File "/home/user_n/anaconda3/envs/env_proj_8/lib/python3.10/site-packages/streamlit/runtime/caching/hashing.py", line 341, in update
    b = self.to_bytes(obj)
  File "/home/user_n/anaconda3/envs/env_proj_8/lib/python3.10/site-packages/streamlit/runtime/caching/hashing.py", line 323, in to_bytes
    b = b"%s:%s" % (tname, self._to_bytes(obj))
  File "/home/user_n/anaconda3/envs/env_proj_8/lib/python3.10/site-packages/streamlit/runtime/caching/hashing.py", line 554, in _to_bytes
    raise UnhashableTypeError() from ex
streamlit.runtime.caching.cache_errors.UnhashableTypeError

During handling of the above exception, another exception occurred:

Traceback (most recent call last):
  File "/home/user_n/anaconda3/envs/env_proj_8/lib/python3.10/site-packages/streamlit/runtime/scriptrunner/script_runner.py", line 589, in _run_script
    exec(code, module.__dict__)
  File "/home/user_n/Documents/Dev/git/project_8/pages/👨‍🏫_dashboard.py", line 81, in <module>
    my.plot_shap_violins(dir_out, df_X, li_new_features, frame_right)
  File "/home/user_n/anaconda3/envs/env_proj_8/lib/python3.10/site-packages/streamlit/runtime/caching/cache_utils.py", line 168, in wrapper
    return cached_func(*args, **kwargs)
  File "/home/user_n/anaconda3/envs/env_proj_8/lib/python3.10/site-packages/streamlit/runtime/caching/cache_utils.py", line 197, in __call__
    return self._get_or_create_cached_value(args, kwargs)
  File "/home/user_n/anaconda3/envs/env_proj_8/lib/python3.10/site-packages/streamlit/runtime/caching/cache_utils.py", line 211, in _get_or_create_cached_value
    value_key = _make_value_key(
  File "/home/user_n/anaconda3/envs/env_proj_8/lib/python3.10/site-packages/streamlit/runtime/caching/cache_utils.py", line 417, in _make_value_key
    raise UnhashableParamError(cache_type, func, arg_name, arg_value, exc)
  File "/home/user_n/anaconda3/envs/env_proj_8/lib/python3.10/site-packages/streamlit/runtime/caching/cache_utils.py", line 409, in _make_value_key
    update_hash(
  File "/home/user_n/anaconda3/envs/env_proj_8/lib/python3.10/site-packages/streamlit/runtime/caching/hashing.py", line 158, in update_hash
    ch.update(hasher, val)
  File "/home/user_n/anaconda3/envs/env_proj_8/lib/python3.10/site-packages/streamlit/runtime/caching/hashing.py", line 341, in update
    b = self.to_bytes(obj)
  File "/home/user_n/anaconda3/envs/env_proj_8/lib/python3.10/site-packages/streamlit/runtime/caching/hashing.py", line 323, in to_bytes
    b = b"%s:%s" % (tname, self._to_bytes(obj))
  File "/home/user_n/anaconda3/envs/env_proj_8/lib/python3.10/site-packages/streamlit/runtime/caching/hashing.py", line 554, in _to_bytes
    raise UnhashableTypeError() from ex
streamlit.runtime.caching.cache_errors.UnhashableParamError: Cannot hash argument 'frame' (of type `streamlit.delta_generator.DeltaGenerator`) in 'plot_shap_violins'.

To address this, you can tell Streamlit not to hash this argument by adding a
leading underscore to the argument's name in the function signature:

```
@st.cache_data
def plot_shap_violins(_frame, ...):
    ...
```
            
  % Total    % Received % Xferd  Average Speed   Time    Time     Time  Current
                                 Dload  Upload   Total   Spent    Left  Speed
  0     0    0     0    0     0      0      0 --:--:-- --:--:-- --:--:--     0100   330  100    37  100   293   1121   8878 --:--:-- --:--:-- --:--:-- 10000
2024-07-09 20:38:17.860 Uncaught app exception
Traceback (most recent call last):
  File "/home/user_n/anaconda3/envs/env_proj_8/lib/python3.10/site-packages/streamlit/runtime/caching/hashing.py", line 552, in _to_bytes
    reduce_data = obj.__reduce__()
  File "/home/user_n/anaconda3/envs/env_proj_8/lib/python3.10/copyreg.py", line 92, in _reduce_ex
    dict = getstate()
  File "/home/user_n/anaconda3/envs/env_proj_8/lib/python3.10/site-packages/streamlit/delta_generator.py", line 345, in wrapper
    raise StreamlitAPIException(message)
streamlit.errors.StreamlitAPIException: `__getstate__()` is not a valid Streamlit command.

The above exception was the direct cause of the following exception:

Traceback (most recent call last):
  File "/home/user_n/anaconda3/envs/env_proj_8/lib/python3.10/site-packages/streamlit/runtime/caching/cache_utils.py", line 409, in _make_value_key
    update_hash(
  File "/home/user_n/anaconda3/envs/env_proj_8/lib/python3.10/site-packages/streamlit/runtime/caching/hashing.py", line 158, in update_hash
    ch.update(hasher, val)
  File "/home/user_n/anaconda3/envs/env_proj_8/lib/python3.10/site-packages/streamlit/runtime/caching/hashing.py", line 341, in update
    b = self.to_bytes(obj)
  File "/home/user_n/anaconda3/envs/env_proj_8/lib/python3.10/site-packages/streamlit/runtime/caching/hashing.py", line 323, in to_bytes
    b = b"%s:%s" % (tname, self._to_bytes(obj))
  File "/home/user_n/anaconda3/envs/env_proj_8/lib/python3.10/site-packages/streamlit/runtime/caching/hashing.py", line 554, in _to_bytes
    raise UnhashableTypeError() from ex
streamlit.runtime.caching.cache_errors.UnhashableTypeError

During handling of the above exception, another exception occurred:

Traceback (most recent call last):
  File "/home/user_n/anaconda3/envs/env_proj_8/lib/python3.10/site-packages/streamlit/runtime/scriptrunner/script_runner.py", line 589, in _run_script
    exec(code, module.__dict__)
  File "/home/user_n/Documents/Dev/git/project_8/pages/👨‍🏫_dashboard.py", line 81, in <module>
    my.plot_shap_violins(dir_out, df_X, li_new_features, frame_right)
  File "/home/user_n/anaconda3/envs/env_proj_8/lib/python3.10/site-packages/streamlit/runtime/caching/cache_utils.py", line 168, in wrapper
    return cached_func(*args, **kwargs)
  File "/home/user_n/anaconda3/envs/env_proj_8/lib/python3.10/site-packages/streamlit/runtime/caching/cache_utils.py", line 197, in __call__
    return self._get_or_create_cached_value(args, kwargs)
  File "/home/user_n/anaconda3/envs/env_proj_8/lib/python3.10/site-packages/streamlit/runtime/caching/cache_utils.py", line 211, in _get_or_create_cached_value
    value_key = _make_value_key(
  File "/home/user_n/anaconda3/envs/env_proj_8/lib/python3.10/site-packages/streamlit/runtime/caching/cache_utils.py", line 417, in _make_value_key
    raise UnhashableParamError(cache_type, func, arg_name, arg_value, exc)
  File "/home/user_n/anaconda3/envs/env_proj_8/lib/python3.10/site-packages/streamlit/runtime/caching/cache_utils.py", line 409, in _make_value_key
    update_hash(
  File "/home/user_n/anaconda3/envs/env_proj_8/lib/python3.10/site-packages/streamlit/runtime/caching/hashing.py", line 158, in update_hash
    ch.update(hasher, val)
  File "/home/user_n/anaconda3/envs/env_proj_8/lib/python3.10/site-packages/streamlit/runtime/caching/hashing.py", line 341, in update
    b = self.to_bytes(obj)
  File "/home/user_n/anaconda3/envs/env_proj_8/lib/python3.10/site-packages/streamlit/runtime/caching/hashing.py", line 323, in to_bytes
    b = b"%s:%s" % (tname, self._to_bytes(obj))
  File "/home/user_n/anaconda3/envs/env_proj_8/lib/python3.10/site-packages/streamlit/runtime/caching/hashing.py", line 554, in _to_bytes
    raise UnhashableTypeError() from ex
streamlit.runtime.caching.cache_errors.UnhashableParamError: Cannot hash argument 'frame' (of type `streamlit.delta_generator.DeltaGenerator`) in 'plot_shap_violins'.

To address this, you can tell Streamlit not to hash this argument by adding a
leading underscore to the argument's name in the function signature:

```
@st.cache_data
def plot_shap_violins(_frame, ...):
    ...
```
            
  % Total    % Received % Xferd  Average Speed   Time    Time     Time  Current
                                 Dload  Upload   Total   Spent    Left  Speed
  0     0    0     0    0     0      0      0 --:--:-- --:--:-- --:--:--     0100   330  100    37  100   293   1121   8878 --:--:-- --:--:-- --:--:-- 10000
2024-07-09 21:45:48.225 Uncaught app exception
Traceback (most recent call last):
  File "/home/user_n/anaconda3/envs/env_proj_8/lib/python3.10/site-packages/streamlit/runtime/caching/hashing.py", line 552, in _to_bytes
    reduce_data = obj.__reduce__()
  File "/home/user_n/anaconda3/envs/env_proj_8/lib/python3.10/copyreg.py", line 92, in _reduce_ex
    dict = getstate()
  File "/home/user_n/anaconda3/envs/env_proj_8/lib/python3.10/site-packages/streamlit/delta_generator.py", line 345, in wrapper
    raise StreamlitAPIException(message)
streamlit.errors.StreamlitAPIException: `__getstate__()` is not a valid Streamlit command.

The above exception was the direct cause of the following exception:

Traceback (most recent call last):
  File "/home/user_n/anaconda3/envs/env_proj_8/lib/python3.10/site-packages/streamlit/runtime/caching/cache_utils.py", line 409, in _make_value_key
    update_hash(
  File "/home/user_n/anaconda3/envs/env_proj_8/lib/python3.10/site-packages/streamlit/runtime/caching/hashing.py", line 158, in update_hash
    ch.update(hasher, val)
  File "/home/user_n/anaconda3/envs/env_proj_8/lib/python3.10/site-packages/streamlit/runtime/caching/hashing.py", line 341, in update
    b = self.to_bytes(obj)
  File "/home/user_n/anaconda3/envs/env_proj_8/lib/python3.10/site-packages/streamlit/runtime/caching/hashing.py", line 323, in to_bytes
    b = b"%s:%s" % (tname, self._to_bytes(obj))
  File "/home/user_n/anaconda3/envs/env_proj_8/lib/python3.10/site-packages/streamlit/runtime/caching/hashing.py", line 554, in _to_bytes
    raise UnhashableTypeError() from ex
streamlit.runtime.caching.cache_errors.UnhashableTypeError

During handling of the above exception, another exception occurred:

Traceback (most recent call last):
  File "/home/user_n/anaconda3/envs/env_proj_8/lib/python3.10/site-packages/streamlit/runtime/scriptrunner/script_runner.py", line 589, in _run_script
    exec(code, module.__dict__)
  File "/home/user_n/Documents/Dev/git/project_8/pages/👨‍🏫_dashboard.py", line 81, in <module>
    my.plot_shap_violins(dir_out, df_X, li_new_features, frame_right)
  File "/home/user_n/anaconda3/envs/env_proj_8/lib/python3.10/site-packages/streamlit/runtime/caching/cache_utils.py", line 168, in wrapper
    return cached_func(*args, **kwargs)
  File "/home/user_n/anaconda3/envs/env_proj_8/lib/python3.10/site-packages/streamlit/runtime/caching/cache_utils.py", line 197, in __call__
    return self._get_or_create_cached_value(args, kwargs)
  File "/home/user_n/anaconda3/envs/env_proj_8/lib/python3.10/site-packages/streamlit/runtime/caching/cache_utils.py", line 211, in _get_or_create_cached_value
    value_key = _make_value_key(
  File "/home/user_n/anaconda3/envs/env_proj_8/lib/python3.10/site-packages/streamlit/runtime/caching/cache_utils.py", line 417, in _make_value_key
    raise UnhashableParamError(cache_type, func, arg_name, arg_value, exc)
  File "/home/user_n/anaconda3/envs/env_proj_8/lib/python3.10/site-packages/streamlit/runtime/caching/cache_utils.py", line 409, in _make_value_key
    update_hash(
  File "/home/user_n/anaconda3/envs/env_proj_8/lib/python3.10/site-packages/streamlit/runtime/caching/hashing.py", line 158, in update_hash
    ch.update(hasher, val)
  File "/home/user_n/anaconda3/envs/env_proj_8/lib/python3.10/site-packages/streamlit/runtime/caching/hashing.py", line 341, in update
    b = self.to_bytes(obj)
  File "/home/user_n/anaconda3/envs/env_proj_8/lib/python3.10/site-packages/streamlit/runtime/caching/hashing.py", line 323, in to_bytes
    b = b"%s:%s" % (tname, self._to_bytes(obj))
  File "/home/user_n/anaconda3/envs/env_proj_8/lib/python3.10/site-packages/streamlit/runtime/caching/hashing.py", line 554, in _to_bytes
    raise UnhashableTypeError() from ex
streamlit.runtime.caching.cache_errors.UnhashableParamError: Cannot hash argument 'st_frame' (of type `streamlit.delta_generator.DeltaGenerator`) in 'plot_shap_violins'.

To address this, you can tell Streamlit not to hash this argument by adding a
leading underscore to the argument's name in the function signature:

```
@st.cache_data
def plot_shap_violins(_st_frame, ...):
    ...
```
            
  % Total    % Received % Xferd  Average Speed   Time    Time     Time  Current
                                 Dload  Upload   Total   Spent    Left  Speed
  0     0    0     0    0     0      0      0 --:--:-- --:--:-- --:--:--     0100   330  100    37  100   293   1027   8138 --:--:-- --:--:-- --:--:--  9166
/home/user_n/anaconda3/envs/env_proj_8/lib/python3.10/site-packages/shap/plots/_beeswarm.py:952: UserWarning:

FigureCanvasAgg is non-interactive, and thus cannot be shown

2024-07-09 21:47:20.428 Uncaught app exception
Traceback (most recent call last):
  File "/home/user_n/anaconda3/envs/env_proj_8/lib/python3.10/site-packages/streamlit/runtime/scriptrunner/script_runner.py", line 589, in _run_script
    exec(code, module.__dict__)
  File "/home/user_n/Documents/Dev/git/project_8/pages/👨‍🏫_dashboard.py", line 84, in <module>
    shap.plots.waterfall(explainer(df_X)[selected_ref], max_display=7)
NameError: name 'explainer' is not defined
  % Total    % Received % Xferd  Average Speed   Time    Time     Time  Current
                                 Dload  Upload   Total   Spent    Left  Speed
  0     0    0     0    0     0      0      0 --:--:-- --:--:-- --:--:--     0100   330  100    37  100   293   2176  17235 --:--:-- --:--:-- --:--:-- 19411
2024-07-09 22:57:33.031 Uncaught app exception
Traceback (most recent call last):
  File "/home/user_n/anaconda3/envs/env_proj_8/lib/python3.10/site-packages/streamlit/runtime/caching/cached_message_replay.py", line 410, in replay_cached_messages
    dg = returned_dgs[msg.id_of_dg_called_on]
KeyError: '140400825502352'

During handling of the above exception, another exception occurred:

Traceback (most recent call last):
  File "/home/user_n/anaconda3/envs/env_proj_8/lib/python3.10/site-packages/streamlit/runtime/scriptrunner/script_runner.py", line 589, in _run_script
    exec(code, module.__dict__)
  File "/home/user_n/Documents/Dev/git/project_8/pages/👨‍🏫_dashboard.py", line 81, in <module>
    my.plot_shap_violins(dir_out, df_X, li_new_features, frame_right)
  File "/home/user_n/anaconda3/envs/env_proj_8/lib/python3.10/site-packages/streamlit/runtime/caching/cache_utils.py", line 168, in wrapper
    return cached_func(*args, **kwargs)
  File "/home/user_n/anaconda3/envs/env_proj_8/lib/python3.10/site-packages/streamlit/runtime/caching/cache_utils.py", line 197, in __call__
    return self._get_or_create_cached_value(args, kwargs)
  File "/home/user_n/anaconda3/envs/env_proj_8/lib/python3.10/site-packages/streamlit/runtime/caching/cache_utils.py", line 221, in _get_or_create_cached_value
    return self._handle_cache_hit(cached_result)
  File "/home/user_n/anaconda3/envs/env_proj_8/lib/python3.10/site-packages/streamlit/runtime/caching/cache_utils.py", line 228, in _handle_cache_hit
    replay_cached_messages(
  File "/home/user_n/anaconda3/envs/env_proj_8/lib/python3.10/site-packages/streamlit/runtime/caching/cached_message_replay.py", line 419, in replay_cached_messages
    raise CacheReplayClosureError(cache_type, cached_func)
streamlit.runtime.caching.cache_errors.CacheReplayClosureError: While running `plot_shap_violins()`, a streamlit element is called on some layout block created outside the function.
This is incompatible with replaying the cached effect of that element, because the
the referenced block might not exist when the replay happens.

How to fix this:
* Move the creation of $THING inside `plot_shap_violins()`.
* Move the call to the streamlit element outside of `plot_shap_violins()`.
* Remove the `@st.cache_data` decorator from `plot_shap_violins()`.
            
  % Total    % Received % Xferd  Average Speed   Time    Time     Time  Current
                                 Dload  Upload   Total   Spent    Left  Speed
  0     0    0     0    0     0      0      0 --:--:-- --:--:-- --:--:--     0100   330  100    37  100   293    787   6234 --:--:-- --:--:-- --:--:--  7173
2024-07-09 23:02:40.137 Uncaught app exception
Traceback (most recent call last):
  File "/home/user_n/anaconda3/envs/env_proj_8/lib/python3.10/site-packages/streamlit/runtime/caching/cached_message_replay.py", line 410, in replay_cached_messages
    dg = returned_dgs[msg.id_of_dg_called_on]
KeyError: '140400825502352'

During handling of the above exception, another exception occurred:

Traceback (most recent call last):
  File "/home/user_n/anaconda3/envs/env_proj_8/lib/python3.10/site-packages/streamlit/runtime/scriptrunner/script_runner.py", line 589, in _run_script
    exec(code, module.__dict__)
  File "/home/user_n/Documents/Dev/git/project_8/pages/👨‍🏫_dashboard.py", line 81, in <module>
    my.plot_shap_violins(dir_out, df_X, li_new_features, frame_right)
  File "/home/user_n/anaconda3/envs/env_proj_8/lib/python3.10/site-packages/streamlit/runtime/caching/cache_utils.py", line 168, in wrapper
    return cached_func(*args, **kwargs)
  File "/home/user_n/anaconda3/envs/env_proj_8/lib/python3.10/site-packages/streamlit/runtime/caching/cache_utils.py", line 197, in __call__
    return self._get_or_create_cached_value(args, kwargs)
  File "/home/user_n/anaconda3/envs/env_proj_8/lib/python3.10/site-packages/streamlit/runtime/caching/cache_utils.py", line 221, in _get_or_create_cached_value
    return self._handle_cache_hit(cached_result)
  File "/home/user_n/anaconda3/envs/env_proj_8/lib/python3.10/site-packages/streamlit/runtime/caching/cache_utils.py", line 228, in _handle_cache_hit
    replay_cached_messages(
  File "/home/user_n/anaconda3/envs/env_proj_8/lib/python3.10/site-packages/streamlit/runtime/caching/cached_message_replay.py", line 419, in replay_cached_messages
    raise CacheReplayClosureError(cache_type, cached_func)
streamlit.runtime.caching.cache_errors.CacheReplayClosureError: While running `plot_shap_violins()`, a streamlit element is called on some layout block created outside the function.
This is incompatible with replaying the cached effect of that element, because the
the referenced block might not exist when the replay happens.

How to fix this:
* Move the creation of $THING inside `plot_shap_violins()`.
* Move the call to the streamlit element outside of `plot_shap_violins()`.
* Remove the `@st.cache_data` decorator from `plot_shap_violins()`.
            
  % Total    % Received % Xferd  Average Speed   Time    Time     Time  Current
                                 Dload  Upload   Total   Spent    Left  Speed
  0     0    0     0    0     0      0      0 --:--:-- --:--:-- --:--:--     0100   330  100    37  100   293   1233   9766 --:--:-- --:--:-- --:--:-- 11000
/home/user_n/anaconda3/envs/env_proj_8/lib/python3.10/site-packages/shap/plots/_beeswarm.py:952: UserWarning:

FigureCanvasAgg is non-interactive, and thus cannot be shown

2024-07-09 23:15:48.623 Uncaught app exception
Traceback (most recent call last):
  File "/home/user_n/anaconda3/envs/env_proj_8/lib/python3.10/site-packages/streamlit/runtime/scriptrunner/script_runner.py", line 589, in _run_script
    exec(code, module.__dict__)
  File "/home/user_n/Documents/Dev/git/project_8/pages/👨‍🏫_dashboard.py", line 93, in <module>
    shap.plots.waterfall(explainer_X[selected_ref], max_display=7)
IndexError: index 155094 is out of bounds for axis 0 with size 48678
  % Total    % Received % Xferd  Average Speed   Time    Time     Time  Current
                                 Dload  Upload   Total   Spent    Left  Speed
  0     0    0     0    0     0      0      0 --:--:-- --:--:-- --:--:--     0100   330  100    37  100   293   1193   9451 --:--:-- --:--:-- --:--:-- 10645
2024-07-09 23:21:10.546 Uncaught app exception
Traceback (most recent call last):
  File "/home/user_n/anaconda3/envs/env_proj_8/lib/python3.10/site-packages/streamlit/runtime/caching/cached_message_replay.py", line 410, in replay_cached_messages
    dg = returned_dgs[msg.id_of_dg_called_on]
KeyError: '140400820454208'

During handling of the above exception, another exception occurred:

Traceback (most recent call last):
  File "/home/user_n/anaconda3/envs/env_proj_8/lib/python3.10/site-packages/streamlit/runtime/scriptrunner/script_runner.py", line 589, in _run_script
    exec(code, module.__dict__)
  File "/home/user_n/Documents/Dev/git/project_8/pages/👨‍🏫_dashboard.py", line 88, in <module>
    plot_shap_violins()
  File "/home/user_n/anaconda3/envs/env_proj_8/lib/python3.10/site-packages/streamlit/runtime/caching/cache_utils.py", line 168, in wrapper
    return cached_func(*args, **kwargs)
  File "/home/user_n/anaconda3/envs/env_proj_8/lib/python3.10/site-packages/streamlit/runtime/caching/cache_utils.py", line 197, in __call__
    return self._get_or_create_cached_value(args, kwargs)
  File "/home/user_n/anaconda3/envs/env_proj_8/lib/python3.10/site-packages/streamlit/runtime/caching/cache_utils.py", line 221, in _get_or_create_cached_value
    return self._handle_cache_hit(cached_result)
  File "/home/user_n/anaconda3/envs/env_proj_8/lib/python3.10/site-packages/streamlit/runtime/caching/cache_utils.py", line 228, in _handle_cache_hit
    replay_cached_messages(
  File "/home/user_n/anaconda3/envs/env_proj_8/lib/python3.10/site-packages/streamlit/runtime/caching/cached_message_replay.py", line 419, in replay_cached_messages
    raise CacheReplayClosureError(cache_type, cached_func)
streamlit.runtime.caching.cache_errors.CacheReplayClosureError: While running `plot_shap_violins()`, a streamlit element is called on some layout block created outside the function.
This is incompatible with replaying the cached effect of that element, because the
the referenced block might not exist when the replay happens.

How to fix this:
* Move the creation of $THING inside `plot_shap_violins()`.
* Move the call to the streamlit element outside of `plot_shap_violins()`.
* Remove the `@st.cache_data` decorator from `plot_shap_violins()`.
            
  % Total    % Received % Xferd  Average Speed   Time    Time     Time  Current
                                 Dload  Upload   Total   Spent    Left  Speed
  0     0    0     0    0     0      0      0 --:--:-- --:--:-- --:--:--     0100   330  100    37  100   293   1370  10851 --:--:-- --:--:-- --:--:-- 12222
/home/user_n/anaconda3/envs/env_proj_8/lib/python3.10/site-packages/shap/plots/_beeswarm.py:952: UserWarning:

FigureCanvasAgg is non-interactive, and thus cannot be shown

  % Total    % Received % Xferd  Average Speed   Time    Time     Time  Current
                                 Dload  Upload   Total   Spent    Left  Speed
  0     0    0     0    0     0      0      0 --:--:-- --:--:-- --:--:--     0100   330  100    37  100   293   2055  16277 --:--:-- --:--:-- --:--:-- 18333
/home/user_n/anaconda3/envs/env_proj_8/lib/python3.10/site-packages/shap/plots/_beeswarm.py:952: UserWarning:

FigureCanvasAgg is non-interactive, and thus cannot be shown

  % Total    % Received % Xferd  Average Speed   Time    Time     Time  Current
                                 Dload  Upload   Total   Spent    Left  Speed
  0     0    0     0    0     0      0      0 --:--:-- --:--:-- --:--:--     0100   330  100    37  100   293    616   4883 --:--:-- --:--:-- --:--:--  5500
/home/user_n/anaconda3/envs/env_proj_8/lib/python3.10/site-packages/shap/plots/_beeswarm.py:952: UserWarning:

FigureCanvasAgg is non-interactive, and thus cannot be shown

  % Total    % Received % Xferd  Average Speed   Time    Time     Time  Current
                                 Dload  Upload   Total   Spent    Left  Speed
  0     0    0     0    0     0      0      0 --:--:-- --:--:-- --:--:--     0100   330  100    37  100   293    822   6511 --:--:-- --:--:-- --:--:--  7333
/home/user_n/anaconda3/envs/env_proj_8/lib/python3.10/site-packages/shap/plots/_beeswarm.py:952: UserWarning:

FigureCanvasAgg is non-interactive, and thus cannot be shown

  % Total    % Received % Xferd  Average Speed   Time    Time     Time  Current
                                 Dload  Upload   Total   Spent    Left  Speed
  0     0    0     0    0     0      0      0 --:--:-- --:--:-- --:--:--     0100   330  100    37  100   293    860   6813 --:--:-- --:--:-- --:--:--  7674
/home/user_n/anaconda3/envs/env_proj_8/lib/python3.10/site-packages/shap/plots/_beeswarm.py:952: UserWarning:

FigureCanvasAgg is non-interactive, and thus cannot be shown

  % Total    % Received % Xferd  Average Speed   Time    Time     Time  Current
                                 Dload  Upload   Total   Spent    Left  Speed
  0     0    0     0    0     0      0      0 --:--:-- --:--:-- --:--:--     0100   330  100    37  100   293   1088   8617 --:--:-- --:--:-- --:--:--  9705
/home/user_n/anaconda3/envs/env_proj_8/lib/python3.10/site-packages/shap/plots/_beeswarm.py:952: UserWarning:

FigureCanvasAgg is non-interactive, and thus cannot be shown

2024-07-09 23:26:24.090 Uncaught app exception
Traceback (most recent call last):
  File "/home/user_n/anaconda3/envs/env_proj_8/lib/python3.10/site-packages/streamlit/runtime/scriptrunner/script_runner.py", line 589, in _run_script
    exec(code, module.__dict__)
  File "/home/user_n/Documents/Dev/git/project_8/pages/👨‍🏫_dashboard.py", line 91, in <module>
    eval(graph_violins)
TypeError: eval() arg 1 must be a string, bytes or code object
  % Total    % Received % Xferd  Average Speed   Time    Time     Time  Current
                                 Dload  Upload   Total   Spent    Left  Speed
  0     0    0     0    0     0      0      0 --:--:-- --:--:-- --:--:--     0100   330  100    37  100   293   1275  10103 --:--:-- --:--:-- --:--:-- 11785
2024-07-09 23:29:13.391 Uncaught app exception
Traceback (most recent call last):
  File "/home/user_n/anaconda3/envs/env_proj_8/lib/python3.10/site-packages/streamlit/runtime/scriptrunner/script_runner.py", line 589, in _run_script
    exec(code, module.__dict__)
  File "/home/user_n/Documents/Dev/git/project_8/pages/👨‍🏫_dashboard.py", line 91, in <module>
    eval(graph_violins)
TypeError: eval() arg 1 must be a string, bytes or code object
  % Total    % Received % Xferd  Average Speed   Time    Time     Time  Current
                                 Dload  Upload   Total   Spent    Left  Speed
  0     0    0     0    0     0      0      0 --:--:-- --:--:-- --:--:--     0100   330  100    37  100   293   1480  11720 --:--:-- --:--:-- --:--:-- 13200
  % Total    % Received % Xferd  Average Speed   Time    Time     Time  Current
                                 Dload  Upload   Total   Spent    Left  Speed
  0     0    0     0    0     0      0      0 --:--:-- --:--:-- --:--:--     0100   330  100    37  100   293    711   5634 --:--:-- --:--:-- --:--:--  6346
  % Total    % Received % Xferd  Average Speed   Time    Time     Time  Current
                                 Dload  Upload   Total   Spent    Left  Speed
  0     0    0     0    0     0      0      0 --:--:-- --:--:-- --:--:--     0100   330  100    37  100   293    880   6976 --:--:-- --:--:-- --:--:--  7857
2024-07-09 23:34:23.925 Uncaught app exception
Traceback (most recent call last):
  File "/home/user_n/anaconda3/envs/env_proj_8/lib/python3.10/site-packages/streamlit/runtime/scriptrunner/script_runner.py", line 589, in _run_script
    exec(code, module.__dict__)
  File "/home/user_n/Documents/Dev/git/project_8/pages/👨‍🏫_dashboard.py", line 87, in <module>
    np_shap_values = load_np(dir_out + 'shap_values.npy')
NameError: name 'load_np' is not defined
  % Total    % Received % Xferd  Average Speed   Time    Time     Time  Current
                                 Dload  Upload   Total   Spent    Left  Speed
  0     0    0     0    0     0      0      0 --:--:-- --:--:-- --:--:--     0100   330  100    37  100   293   1947  15421 --:--:-- --:--:-- --:--:-- 17368
  % Total    % Received % Xferd  Average Speed   Time    Time     Time  Current
                                 Dload  Upload   Total   Spent    Left  Speed
  0     0    0     0    0     0      0      0 --:--:-- --:--:-- --:--:--     0100   330  100    37  100   293    740   5860 --:--:-- --:--:-- --:--:--  6600
  % Total    % Received % Xferd  Average Speed   Time    Time     Time  Current
                                 Dload  Upload   Total   Spent    Left  Speed
  0     0    0     0    0     0      0      0 --:--:-- --:--:-- --:--:--     0100   330  100    37  100   293   1057   8371 --:--:-- --:--:-- --:--:--  9166100   330  100    37  100   293   1057   8371 --:--:-- --:--:-- --:--:--  9166
  % Total    % Received % Xferd  Average Speed   Time    Time     Time  Current
                                 Dload  Upload   Total   Spent    Left  Speed
  0     0    0     0    0     0      0      0 --:--:-- --:--:-- --:--:--     0100   330  100    37  100   293   1370  10851 --:--:-- --:--:-- --:--:-- 12222
  % Total    % Received % Xferd  Average Speed   Time    Time     Time  Current
                                 Dload  Upload   Total   Spent    Left  Speed
  0     0    0     0    0     0      0      0 --:--:-- --:--:-- --:--:--     0100   330  100    37  100   293   1761  13952 --:--:-- --:--:-- --:--:-- 16500
  % Total    % Received % Xferd  Average Speed   Time    Time     Time  Current
                                 Dload  Upload   Total   Spent    Left  Speed
  0     0    0     0    0     0      0      0 --:--:-- --:--:-- --:--:--     0100   330  100    37  100   293    804   6369 --:--:-- --:--:-- --:--:--  7173
  % Total    % Received % Xferd  Average Speed   Time    Time     Time  Current
                                 Dload  Upload   Total   Spent    Left  Speed
  0     0    0     0    0     0      0      0 --:--:-- --:--:-- --:--:--     0100   330  100    37  100   293   1275  10103 --:--:-- --:--:-- --:--:-- 11379
  % Total    % Received % Xferd  Average Speed   Time    Time     Time  Current
                                 Dload  Upload   Total   Spent    Left  Speed
  0     0    0     0    0     0      0      0 --:--:-- --:--:-- --:--:--     0100   330  100    37  100   293   1156   9156 --:--:-- --:--:-- --:--:-- 10312
  % Total    % Received % Xferd  Average Speed   Time    Time     Time  Current
                                 Dload  Upload   Total   Spent    Left  Speed
  0     0    0     0    0     0      0      0 --:--:-- --:--:-- --:--:--     0100   330  100    37  100   293   1608  12739 --:--:-- --:--:-- --:--:-- 14347
2024-07-09 23:55:17.076 Uncaught app exception
Traceback (most recent call last):
  File "/home/user_n/anaconda3/envs/env_proj_8/lib/python3.10/site-packages/streamlit/runtime/scriptrunner/script_runner.py", line 589, in _run_script
    exec(code, module.__dict__)
  File "/home/user_n/Documents/Dev/git/project_8/pages/👨‍🏫_dashboard.py", line 101, in <module>
    get_violins_image()
  File "/home/user_n/Documents/Dev/git/project_8/pages/👨‍🏫_dashboard.py", line 87, in get_violins_image
    shap.save_image(dir_out + 'shap_violins.png')
AttributeError: module 'shap' has no attribute 'save_image'
  % Total    % Received % Xferd  Average Speed   Time    Time     Time  Current
                                 Dload  Upload   Total   Spent    Left  Speed
  0     0    0     0    0     0      0      0 --:--:-- --:--:-- --:--:--     0100   330  100    37  100   293   2055  16277 --:--:-- --:--:-- --:--:-- 18333
  % Total    % Received % Xferd  Average Speed   Time    Time     Time  Current
                                 Dload  Upload   Total   Spent    Left  Speed
  0     0    0     0    0     0      0      0 --:--:-- --:--:-- --:--:--     0100   330  100    37  100   293   2176  17235 --:--:-- --:--:-- --:--:-- 19411
  % Total    % Received % Xferd  Average Speed   Time    Time     Time  Current
                                 Dload  Upload   Total   Spent    Left  Speed
  0     0    0     0    0     0      0      0 --:--:-- --:--:-- --:--:--     0100   330  100    37  100   293   1275  10103 --:--:-- --:--:-- --:--:-- 11785
  % Total    % Received % Xferd  Average Speed   Time    Time     Time  Current
                                 Dload  Upload   Total   Spent    Left  Speed
  0     0    0     0    0     0      0      0 --:--:-- --:--:-- --:--:--     0100   330  100    37  100   293   2312  18312 --:--:-- --:--:-- --:--:-- 20625
  % Total    % Received % Xferd  Average Speed   Time    Time     Time  Current
                                 Dload  Upload   Total   Spent    Left  Speed
  0     0    0     0    0     0      0      0 --:--:-- --:--:-- --:--:--     0100   330  100    37  100   293   1608  12739 --:--:-- --:--:-- --:--:-- 15000
  % Total    % Received % Xferd  Average Speed   Time    Time     Time  Current
                                 Dload  Upload   Total   Spent    Left  Speed
  0     0    0     0    0     0      0      0 --:--:-- --:--:-- --:--:--     0100   330  100    37  100   293   1057   8371 --:--:-- --:--:-- --:--:--  9705
2024-07-10 00:03:17.757 Uncaught app exception
Traceback (most recent call last):
  File "/home/user_n/anaconda3/envs/env_proj_8/lib/python3.10/site-packages/streamlit/runtime/scriptrunner/script_runner.py", line 589, in _run_script
    exec(code, module.__dict__)
  File "/home/user_n/Documents/Dev/git/project_8/pages/👨‍🏫_dashboard.py", line 112, in <module>
    shap.plots.waterfall(explainer_X[selected_ref], max_display=7)
IndexError: index 155094 is out of bounds for axis 0 with size 48678
2024-07-10 00:03:40.544 Uncaught app exception
Traceback (most recent call last):
  File "/home/user_n/anaconda3/envs/env_proj_8/lib/python3.10/site-packages/streamlit/runtime/scriptrunner/script_runner.py", line 589, in _run_script
    exec(code, module.__dict__)
  File "/home/user_n/Documents/Dev/git/project_8/pages/👨‍🏫_dashboard.py", line 112, in <module>
    shap.plots.waterfall(explainer_X[selected_ref], max_display=7)
IndexError: index 155094 is out of bounds for axis 0 with size 48678
  % Total    % Received % Xferd  Average Speed   Time    Time     Time  Current
                                 Dload  Upload   Total   Spent    Left  Speed
  0     0    0     0    0     0      0      0 --:--:-- --:--:-- --:--:--     0100   330  100    37  100   293    660   5232 --:--:-- --:--:-- --:--:--  6000
  % Total    % Received % Xferd  Average Speed   Time    Time     Time  Current
                                 Dload  Upload   Total   Spent    Left  Speed
  0     0    0     0    0     0      0      0 --:--:-- --:--:-- --:--:--     0100   330  100    37  100   293   1088   8617 --:--:-- --:--:-- --:--:--  9705
  % Total    % Received % Xferd  Average Speed   Time    Time     Time  Current
                                 Dload  Upload   Total   Spent    Left  Speed
  0     0    0     0    0     0      0      0 --:--:-- --:--:-- --:--:--     0100   330  100    37  100   293    925   7325 --:--:-- --:--:-- --:--:--  8250
  % Total    % Received % Xferd  Average Speed   Time    Time     Time  Current
                                 Dload  Upload   Total   Spent    Left  Speed
  0     0    0     0    0     0      0      0 --:--:-- --:--:-- --:--:--     0100   330  100    37  100   293    860   6813 --:--:-- --:--:-- --:--:--  7674
2024-07-10 00:10:36.182 Uncaught app exception
Traceback (most recent call last):
  File "/home/user_n/anaconda3/envs/env_proj_8/lib/python3.10/site-packages/streamlit/runtime/scriptrunner/script_runner.py", line 589, in _run_script
    exec(code, module.__dict__)
  File "/home/user_n/Documents/Dev/git/project_8/pages/👨‍🏫_dashboard.py", line 30, in <module>
    df_data.set_index('request_id', inplace=True)
  File "/home/user_n/anaconda3/envs/env_proj_8/lib/python3.10/site-packages/pandas/core/frame.py", line 6122, in set_index
    raise KeyError(f"None of {missing} are in the columns")
KeyError: "None of ['request_id'] are in the columns"
2024-07-10 00:13:00.341 Uncaught app exception
Traceback (most recent call last):
  File "/home/user_n/anaconda3/envs/env_proj_8/lib/python3.10/site-packages/streamlit/runtime/scriptrunner/script_runner.py", line 589, in _run_script
    exec(code, module.__dict__)
  File "/home/user_n/Documents/Dev/git/project_8/pages/👨‍🏫_dashboard.py", line 30, in <module>
    df_data.set_index('request_id', inplace=True)
  File "/home/user_n/anaconda3/envs/env_proj_8/lib/python3.10/site-packages/pandas/core/frame.py", line 6122, in set_index
    raise KeyError(f"None of {missing} are in the columns")
KeyError: "None of ['request_id'] are in the columns"
2024-07-10 00:14:09.876 Uncaught app exception
Traceback (most recent call last):
  File "/home/user_n/anaconda3/envs/env_proj_8/lib/python3.10/site-packages/streamlit/runtime/scriptrunner/script_runner.py", line 589, in _run_script
    exec(code, module.__dict__)
  File "/home/user_n/Documents/Dev/git/project_8/pages/👨‍🏫_dashboard.py", line 30, in <module>
    df_data.set_index('request_id', inplace=True)
  File "/home/user_n/anaconda3/envs/env_proj_8/lib/python3.10/site-packages/pandas/core/frame.py", line 6122, in set_index
    raise KeyError(f"None of {missing} are in the columns")
KeyError: "None of ['request_id'] are in the columns"
2024-07-10 00:15:24.006 Uncaught app exception
Traceback (most recent call last):
  File "/home/user_n/anaconda3/envs/env_proj_8/lib/python3.10/site-packages/streamlit/runtime/scriptrunner/script_runner.py", line 589, in _run_script
    exec(code, module.__dict__)
  File "/home/user_n/Documents/Dev/git/project_8/pages/👨‍🏫_dashboard.py", line 30, in <module>
    df_data.set_index('request_id', inplace=True)
  File "/home/user_n/anaconda3/envs/env_proj_8/lib/python3.10/site-packages/pandas/core/frame.py", line 6122, in set_index
    raise KeyError(f"None of {missing} are in the columns")
KeyError: "None of ['request_id'] are in the columns"
2024-07-10 00:16:08.999 Uncaught app exception
Traceback (most recent call last):
  File "/home/user_n/anaconda3/envs/env_proj_8/lib/python3.10/site-packages/streamlit/runtime/scriptrunner/script_runner.py", line 589, in _run_script
    exec(code, module.__dict__)
  File "/home/user_n/Documents/Dev/git/project_8/pages/👨‍🏫_dashboard.py", line 30, in <module>
    df_data.set_index('request_id', inplace=True)
  File "/home/user_n/anaconda3/envs/env_proj_8/lib/python3.10/site-packages/pandas/core/frame.py", line 6122, in set_index
    raise KeyError(f"None of {missing} are in the columns")
KeyError: "None of ['request_id'] are in the columns"
2024-07-10 00:16:17.380 Uncaught app exception
Traceback (most recent call last):
  File "/home/user_n/anaconda3/envs/env_proj_8/lib/python3.10/site-packages/streamlit/runtime/scriptrunner/script_runner.py", line 589, in _run_script
    exec(code, module.__dict__)
  File "/home/user_n/Documents/Dev/git/project_8/pages/👨‍🏫_dashboard.py", line 30, in <module>
    df_data.set_index('request_id', inplace=True)
  File "/home/user_n/anaconda3/envs/env_proj_8/lib/python3.10/site-packages/pandas/core/frame.py", line 6122, in set_index
    raise KeyError(f"None of {missing} are in the columns")
KeyError: "None of ['request_id'] are in the columns"
2024-07-10 00:17:32.926 Uncaught app exception
Traceback (most recent call last):
  File "/home/user_n/anaconda3/envs/env_proj_8/lib/python3.10/site-packages/streamlit/runtime/scriptrunner/script_runner.py", line 589, in _run_script
    exec(code, module.__dict__)
  File "/home/user_n/Documents/Dev/git/project_8/pages/👨‍🏫_dashboard.py", line 30, in <module>
    df_data.set_index('request_id', inplace=True)
  File "/home/user_n/anaconda3/envs/env_proj_8/lib/python3.10/site-packages/pandas/core/frame.py", line 6122, in set_index
    raise KeyError(f"None of {missing} are in the columns")
KeyError: "None of ['request_id'] are in the columns"
2024-07-10 00:19:43.086 Uncaught app exception
Traceback (most recent call last):
  File "/home/user_n/anaconda3/envs/env_proj_8/lib/python3.10/site-packages/streamlit/runtime/scriptrunner/script_runner.py", line 589, in _run_script
    exec(code, module.__dict__)
  File "/home/user_n/Documents/Dev/git/project_8/pages/👨‍🏫_dashboard.py", line 12, in <module>
    import my_functions as my                # Custom module
  File "/home/user_n/Documents/Dev/git/project_8/utils/my_functions.py", line 25
    		set_index('request_id')
    		^^^^^^^^^
SyntaxError: invalid syntax
  % Total    % Received % Xferd  Average Speed   Time    Time     Time  Current
                                 Dload  Upload   Total   Spent    Left  Speed
  0     0    0     0    0     0      0      0 --:--:-- --:--:-- --:--:--     0100   330  100    37  100   293   2055  16277 --:--:-- --:--:-- --:--:-- 18333
  % Total    % Received % Xferd  Average Speed   Time    Time     Time  Current
                                 Dload  Upload   Total   Spent    Left  Speed
  0     0    0     0    0     0      0      0 --:--:-- --:--:-- --:--:--     0100   330  100    37  100   293    685   5425 --:--:-- --:--:-- --:--:--  6111
  % Total    % Received % Xferd  Average Speed   Time    Time     Time  Current
                                 Dload  Upload   Total   Spent    Left  Speed
  0     0    0     0    0     0      0      0 --:--:-- --:--:-- --:--:--     0100   330  100    37  100   293   1088   8617 --:--:-- --:--:-- --:--:--  9705
  % Total    % Received % Xferd  Average Speed   Time    Time     Time  Current
                                 Dload  Upload   Total   Spent    Left  Speed
  0     0    0     0    0     0      0      0 --:--:-- --:--:-- --:--:--     0100   330  100    37  100   293    711   5634 --:--:-- --:--:-- --:--:--  6346
  % Total    % Received % Xferd  Average Speed   Time    Time     Time  Current
                                 Dload  Upload   Total   Spent    Left  Speed
  0     0    0     0    0     0      0      0 --:--:-- --:--:-- --:--:--     0100   330  100    37  100   293   1370  10851 --:--:-- --:--:-- --:--:-- 12222
  % Total    % Received % Xferd  Average Speed   Time    Time     Time  Current
                                 Dload  Upload   Total   Spent    Left  Speed
  0     0    0     0    0     0      0      0 --:--:-- --:--:-- --:--:--     0100   330  100    37  100   293   1156   9156 --:--:-- --:--:-- --:--:-- 10312
2024-07-10 00:26:12.804 Uncaught app exception
Traceback (most recent call last):
  File "/home/user_n/anaconda3/envs/env_proj_8/lib/python3.10/site-packages/streamlit/runtime/scriptrunner/script_runner.py", line 589, in _run_script
    exec(code, module.__dict__)
  File "/home/user_n/Documents/Dev/git/project_8/pages/👨‍🏫_dashboard.py", line 112, in <module>
    shap.plots.waterfall(explainer_X[selected_ref], max_display=7)
IndexError: index 155094 is out of bounds for axis 0 with size 48678
  % Total    % Received % Xferd  Average Speed   Time    Time     Time  Current
                                 Dload  Upload   Total   Spent    Left  Speed
  0     0    0     0    0     0      0      0 --:--:-- --:--:-- --:--:--     0100   331  100    37  100   294   1370  10888 --:--:-- --:--:-- --:--:-- 12259
2024-07-10 00:27:35.719 Uncaught app exception
Traceback (most recent call last):
  File "/home/user_n/anaconda3/envs/env_proj_8/lib/python3.10/site-packages/streamlit/runtime/scriptrunner/script_runner.py", line 589, in _run_script
    exec(code, module.__dict__)
  File "/home/user_n/Documents/Dev/git/project_8/pages/👨‍🏫_dashboard.py", line 112, in <module>
    shap.plots.waterfall(explainer_X[selected_ref], max_display=7)
  File "/home/user_n/anaconda3/envs/env_proj_8/lib/python3.10/site-packages/shap/plots/_waterfall.py", line 56, in waterfall
    raise TypeError(emsg)
TypeError: The waterfall plot requires an `Explanation` object as the `shap_values` argument.
  % Total    % Received % Xferd  Average Speed   Time    Time     Time  Current
                                 Dload  Upload   Total   Spent    Left  Speed
  0     0    0     0    0     0      0      0 --:--:-- --:--:-- --:--:--     0100   330  100    37  100   293   1480  11720 --:--:-- --:--:-- --:--:-- 13200
2024-07-10 00:32:18.769 Uncaught app exception
Traceback (most recent call last):
  File "/home/user_n/anaconda3/envs/env_proj_8/lib/python3.10/site-packages/streamlit/runtime/scriptrunner/script_runner.py", line 589, in _run_script
    exec(code, module.__dict__)
  File "/home/user_n/Documents/Dev/git/project_8/pages/👨‍🏫_dashboard.py", line 111, in <module>
    st.write('row_number =' + df_X.index.get_loc(selected_ref))
TypeError: can only concatenate str (not "int") to str
  % Total    % Received % Xferd  Average Speed   Time    Time     Time  Current
                                 Dload  Upload   Total   Spent    Left  Speed
  0     0    0     0    0     0      0      0 --:--:-- --:--:-- --:--:--     0100   330  100    37  100   293   1088   8617 --:--:-- --:--:-- --:--:-- 10000
  % Total    % Received % Xferd  Average Speed   Time    Time     Time  Current
                                 Dload  Upload   Total   Spent    Left  Speed
  0     0    0     0    0     0      0      0 --:--:-- --:--:-- --:--:--     0100   330  100    37  100   293    925   7325 --:--:-- --:--:-- --:--:--  8250
  % Total    % Received % Xferd  Average Speed   Time    Time     Time  Current
                                 Dload  Upload   Total   Spent    Left  Speed
  0     0    0     0    0     0      0      0 --:--:-- --:--:-- --:--:--     0100   331  100    37  100   294   1370  10888 --:--:-- --:--:-- --:--:-- 12259
  % Total    % Received % Xferd  Average Speed   Time    Time     Time  Current
                                 Dload  Upload   Total   Spent    Left  Speed
  0     0    0     0    0     0      0      0 --:--:-- --:--:-- --:--:--     0100   330  100    37  100   293   1156   9156 --:--:-- --:--:-- --:--:-- 10312
2024-07-10 00:33:51.157 Uncaught app exception
Traceback (most recent call last):
  File "/home/user_n/anaconda3/envs/env_proj_8/lib/python3.10/site-packages/streamlit/runtime/scriptrunner/script_runner.py", line 589, in _run_script
    exec(code, module.__dict__)
  File "/home/user_n/Documents/Dev/git/project_8/pages/👨‍🏫_dashboard.py", line 115, in <module>
    shap.plots.waterfall(explainer_X[row_number], max_display=7)
  File "/home/user_n/anaconda3/envs/env_proj_8/lib/python3.10/site-packages/shap/plots/_waterfall.py", line 56, in waterfall
    raise TypeError(emsg)
TypeError: The waterfall plot requires an `Explanation` object as the `shap_values` argument.
  % Total    % Received % Xferd  Average Speed   Time    Time     Time  Current
                                 Dload  Upload   Total   Spent    Left  Speed
  0     0    0     0    0     0      0      0 --:--:-- --:--:-- --:--:--     0100   330  100    37  100   293    770   6104 --:--:-- --:--:-- --:--:--  6875
2024-07-10 00:44:40.788 Uncaught app exception
Traceback (most recent call last):
  File "/home/user_n/anaconda3/envs/env_proj_8/lib/python3.10/site-packages/streamlit/runtime/scriptrunner/script_runner.py", line 589, in _run_script
    exec(code, module.__dict__)
  File "/home/user_n/Documents/Dev/git/project_8/pages/👨‍🏫_dashboard.py", line 121, in <module>
    explainer_X = pickle.load(f)
NameError: name 'pickle' is not defined
  % Total    % Received % Xferd  Average Speed   Time    Time     Time  Current
                                 Dload  Upload   Total   Spent    Left  Speed
  0     0    0     0    0     0      0      0 --:--:-- --:--:-- --:--:--     0 88   330    0     0  100   293      0  13952 --:--:-- --:--:-- --:--:-- 13318100   330  100    37  100   293   1761  13952 --:--:-- --:--:-- --:--:-- 15000
2024-07-10 00:45:02.277 Uncaught app exception
Traceback (most recent call last):
  File "/home/user_n/anaconda3/envs/env_proj_8/lib/python3.10/site-packages/streamlit/runtime/scriptrunner/script_runner.py", line 589, in _run_script
    exec(code, module.__dict__)
  File "/home/user_n/Documents/Dev/git/project_8/pages/👨‍🏫_dashboard.py", line 124, in <module>
    shap.plots.waterfall(explainer_X[row_number], max_display=7)
TypeError: 'TreeExplainer' object is not subscriptable
  % Total    % Received % Xferd  Average Speed   Time    Time     Time  Current
                                 Dload  Upload   Total   Spent    Left  Speed
  0     0    0     0    0     0      0      0 --:--:-- --:--:-- --:--:--     0100   330  100    37  100   293   1233   9766 --:--:-- --:--:-- --:--:-- 11000
2024-07-10 00:47:52.015 Uncaught app exception
Traceback (most recent call last):
  File "/home/user_n/anaconda3/envs/env_proj_8/lib/python3.10/site-packages/streamlit/runtime/scriptrunner/script_runner.py", line 589, in _run_script
    exec(code, module.__dict__)
  File "/home/user_n/Documents/Dev/git/project_8/pages/👨‍🏫_dashboard.py", line 125, in <module>
    shap.plots.waterfall(np_shap_values[row_number], max_display=7)
  File "/home/user_n/anaconda3/envs/env_proj_8/lib/python3.10/site-packages/shap/plots/_waterfall.py", line 56, in waterfall
    raise TypeError(emsg)
TypeError: The waterfall plot requires an `Explanation` object as the `shap_values` argument.
  % Total    % Received % Xferd  Average Speed   Time    Time     Time  Current
                                 Dload  Upload   Total   Spent    Left  Speed
  0     0    0     0    0     0      0      0 --:--:-- --:--:-- --:--:--     0100   330  100    37  100   293    725   5745 --:--:-- --:--:-- --:--:--  6470
2024-07-10 00:50:13.722 Uncaught app exception
Traceback (most recent call last):
  File "/home/user_n/anaconda3/envs/env_proj_8/lib/python3.10/site-packages/streamlit/runtime/scriptrunner/script_runner.py", line 589, in _run_script
    exec(code, module.__dict__)
  File "/home/user_n/Documents/Dev/git/project_8/pages/👨‍🏫_dashboard.py", line 125, in <module>
    shap.plots.waterfall(np_shap_values[row_number], max_display=7)
  File "/home/user_n/anaconda3/envs/env_proj_8/lib/python3.10/site-packages/shap/plots/_waterfall.py", line 56, in waterfall
    raise TypeError(emsg)
TypeError: The waterfall plot requires an `Explanation` object as the `shap_values` argument.
  % Total    % Received % Xferd  Average Speed   Time    Time     Time  Current
                                 Dload  Upload   Total   Spent    Left  Speed
  0     0    0     0    0     0      0      0 --:--:-- --:--:-- --:--:--     0100   330  100    37  100   293   1275  10103 --:--:-- --:--:-- --:--:-- 11379
/home/user_n/anaconda3/envs/env_proj_8/lib/python3.10/site-packages/shap/plots/_waterfall.py:315: UserWarning:

FigureCanvasAgg is non-interactive, and thus cannot be shown

  % Total    % Received % Xferd  Average Speed   Time    Time     Time  Current
                                 Dload  Upload   Total   Spent    Left  Speed
  0     0    0     0    0     0      0      0 --:--:-- --:--:-- --:--:--     0100   330  100    37  100   293   1423  11269 --:--:-- --:--:-- --:--:-- 12692
/home/user_n/anaconda3/envs/env_proj_8/lib/python3.10/site-packages/shap/plots/_waterfall.py:315: UserWarning:

FigureCanvasAgg is non-interactive, and thus cannot be shown

  % Total    % Received % Xferd  Average Speed   Time    Time     Time  Current
                                 Dload  Upload   Total   Spent    Left  Speed
  0     0    0     0    0     0      0      0 --:--:-- --:--:-- --:--:--     0100   330  100    37  100   293    840   6659 --:--:-- --:--:-- --:--:--  7500
/home/user_n/anaconda3/envs/env_proj_8/lib/python3.10/site-packages/shap/plots/_waterfall.py:315: UserWarning:

FigureCanvasAgg is non-interactive, and thus cannot be shown

  % Total    % Received % Xferd  Average Speed   Time    Time     Time  Current
                                 Dload  Upload   Total   Spent    Left  Speed
  0     0    0     0    0     0      0      0 --:--:-- --:--:-- --:--:--     0100   330  100    37  100   293    596   4725 --:--:-- --:--:-- --:--:--  5409
/home/user_n/anaconda3/envs/env_proj_8/lib/python3.10/site-packages/shap/plots/_waterfall.py:315: UserWarning:

FigureCanvasAgg is non-interactive, and thus cannot be shown

  % Total    % Received % Xferd  Average Speed   Time    Time     Time  Current
                                 Dload  Upload   Total   Spent    Left  Speed
  0     0    0     0    0     0      0      0 --:--:-- --:--:-- --:--:--     0100   330  100    37  100   293   1321  10464 --:--:-- --:--:-- --:--:-- 11785
/home/user_n/anaconda3/envs/env_proj_8/lib/python3.10/site-packages/shap/plots/_waterfall.py:315: UserWarning:

FigureCanvasAgg is non-interactive, and thus cannot be shown

  % Total    % Received % Xferd  Average Speed   Time    Time     Time  Current
                                 Dload  Upload   Total   Spent    Left  Speed
  0     0    0     0    0     0      0      0 --:--:-- --:--:-- --:--:--     0100   330  100    37  100   293    596   4725 --:--:-- --:--:-- --:--:--  5322
/home/user_n/anaconda3/envs/env_proj_8/lib/python3.10/site-packages/shap/plots/_waterfall.py:315: UserWarning:

FigureCanvasAgg is non-interactive, and thus cannot be shown

  % Total    % Received % Xferd  Average Speed   Time    Time     Time  Current
                                 Dload  Upload   Total   Spent    Left  Speed
  0     0    0     0    0     0      0      0 --:--:-- --:--:-- --:--:--     0  0     0    0     0    0     0      0      0 --:--:-- --:--:-- --:--:--     0100   330  100    37  100   293   1541  12208 --:--:-- --:--:-- --:--:-- 13200
/home/user_n/anaconda3/envs/env_proj_8/lib/python3.10/site-packages/shap/plots/_waterfall.py:315: UserWarning:

FigureCanvasAgg is non-interactive, and thus cannot be shown

  % Total    % Received % Xferd  Average Speed   Time    Time     Time  Current
                                 Dload  Upload   Total   Spent    Left  Speed
  0     0    0     0    0     0      0      0 --:--:-- --:--:-- --:--:--     0100   330  100    37  100   293   1275  10103 --:--:-- --:--:-- --:--:-- 11379
/home/user_n/anaconda3/envs/env_proj_8/lib/python3.10/site-packages/shap/plots/_waterfall.py:315: UserWarning:

FigureCanvasAgg is non-interactive, and thus cannot be shown

  % Total    % Received % Xferd  Average Speed   Time    Time     Time  Current
                                 Dload  Upload   Total   Spent    Left  Speed
  0     0    0     0    0     0      0      0 --:--:-- --:--:-- --:--:--     0100   330  100    37  100   293   2055  16277 --:--:-- --:--:-- --:--:-- 18333
/home/user_n/anaconda3/envs/env_proj_8/lib/python3.10/site-packages/shap/plots/_waterfall.py:315: UserWarning:

FigureCanvasAgg is non-interactive, and thus cannot be shown

  % Total    % Received % Xferd  Average Speed   Time    Time     Time  Current
                                 Dload  Upload   Total   Spent    Left  Speed
  0     0    0     0    0     0      0      0 --:--:-- --:--:-- --:--:--     0100   330  100    37  100   293    925   7325 --:--:-- --:--:-- --:--:--  8461
/home/user_n/anaconda3/envs/env_proj_8/lib/python3.10/site-packages/shap/plots/_waterfall.py:315: UserWarning:

FigureCanvasAgg is non-interactive, and thus cannot be shown

  % Total    % Received % Xferd  Average Speed   Time    Time     Time  Current
                                 Dload  Upload   Total   Spent    Left  Speed
  0     0    0     0    0     0      0      0 --:--:-- --:--:-- --:--:--     0100   330  100    37  100   293   1156   9156 --:--:-- --:--:-- --:--:-- 10645
/home/user_n/anaconda3/envs/env_proj_8/lib/python3.10/site-packages/shap/plots/_waterfall.py:315: UserWarning:

FigureCanvasAgg is non-interactive, and thus cannot be shown

  % Total    % Received % Xferd  Average Speed   Time    Time     Time  Current
                                 Dload  Upload   Total   Spent    Left  Speed
  0     0    0     0    0     0      0      0 --:--:-- --:--:-- --:--:--     0100   330  100    37  100   293    822   6511 --:--:-- --:--:-- --:--:--  7333
/home/user_n/anaconda3/envs/env_proj_8/lib/python3.10/site-packages/shap/plots/_waterfall.py:315: UserWarning:

FigureCanvasAgg is non-interactive, and thus cannot be shown

  % Total    % Received % Xferd  Average Speed   Time    Time     Time  Current
                                 Dload  Upload   Total   Spent    Left  Speed
  0     0    0     0    0     0      0      0 --:--:-- --:--:-- --:--:--     0100   330  100    37  100   293    787   6234 --:--:-- --:--:-- --:--:--  7021
/home/user_n/anaconda3/envs/env_proj_8/lib/python3.10/site-packages/shap/plots/_waterfall.py:315: UserWarning:

FigureCanvasAgg is non-interactive, and thus cannot be shown

  % Total    % Received % Xferd  Average Speed   Time    Time     Time  Current
                                 Dload  Upload   Total   Spent    Left  Speed
  0     0    0     0    0     0      0      0 --:--:-- --:--:-- --:--:--     0100   331  100    37  100   294    840   6681 --:--:-- --:--:-- --:--:--  7522
/home/user_n/anaconda3/envs/env_proj_8/lib/python3.10/site-packages/shap/plots/_waterfall.py:315: UserWarning:

FigureCanvasAgg is non-interactive, and thus cannot be shown

  % Total    % Received % Xferd  Average Speed   Time    Time     Time  Current
                                 Dload  Upload   Total   Spent    Left  Speed
  0     0    0     0    0     0      0      0 --:--:-- --:--:-- --:--:--     0100   332  100    37  100   295   1057   8428 --:--:-- --:--:-- --:--:--  9764
/home/user_n/anaconda3/envs/env_proj_8/lib/python3.10/site-packages/shap/plots/_waterfall.py:315: UserWarning:

FigureCanvasAgg is non-interactive, and thus cannot be shown

